Workbook
Name FG_GolesLocal: WORLDCUP!$AC$4:$AC$97
Name FG_GolesVisitante: WORLDCUP!$AD$4:$AD$97
Name FGLocal: WORLDCUP!$AA$4:$AA$97
Name FGVisitante: WORLDCUP!$AF$4:$AF$97
Name Ganador: WORLDCUP!$D$4:$D$97
Name Grafico: Graf!$A$1:$C$11
Name Grafico_range: _xlfn.ANCHORARRAY(Stats!$H$8)
Name Grafico_vacio: Graf!$F$1
Name Grafico1X2: IF(Stats!$D$34,Grafico,Grafico_vacio)
Name Lista_fechas_rondas: Equipos!$Q$40:INDEX(Equipos!$Q$40:$Q$63,SUMPRODUCT((NOT(ISERROR(Equipos!$Q$40:$Q$63)))*(Equipos!$Q$40:$Q$63<>"")))
Name Part1Empate1L: WORLDCUP!$E$4:$E$97
Name Part1Empate1V: WORLDCUP!$F$4:$F$97
Name Part1Empate2L: WORLDCUP!$H$4:$H$97
Name Part1Empate2V: WORLDCUP!$I$4:$I$97
Name Part1Empate3L: WORLDCUP!$K$4:$K$97
Name Part1Empate3V: WORLDCUP!$L$4:$L$97
Name Part2Empate4L: WORLDCUP!$N$4:$N$97
Name Part2Empate4V: WORLDCUP!$O$4:$O$97
Name Part2Empate5L: WORLDCUP!$Q$4:$Q$97
Name Part2Empate5V: WORLDCUP!$R$4:$R$97
Name Part2Empate6L: WORLDCUP!$T$4:$T$97
Name Part2Empate6V: WORLDCUP!$U$4:$U$97
Name Rango_Admin_Clas: INDEX(ADMIN!$S$1:$DX$5,1,1):INDEX(ADMIN!$S$1:$DX$5,5,ADMIN!$D$5*3)
Name Rango_Admin_Clas_Primera: INDEX(ADMIN!$S$1:$DX$1,1,1):INDEX(ADMIN!$S$1:$DX$1,1,ADMIN!$D$5*3)
Name Rango_Admin_Clas_Total: INDEX(ADMIN!$S$1:$DX$300,1,1):INDEX(ADMIN!$S$1:$DX$300,300,ADMIN!$D$5*3)
Name Rango_Admin_DailyClas: INDEX(ADMIN!$S$263:$DX$267,1,1):INDEX(ADMIN!$S$263:$DX$267,5,ADMIN!$D$5*3)
Name Rango_Admin_DailyClas_Primera: INDEX(ADMIN!$S$263:$DX$263,1,1):INDEX(ADMIN!$S$263:$DX$263,1,ADMIN!$D$5*3)
Name Rango_Admin_DailyPred: INDEX(ADMIN!$K$5:$DX$300,1,1):INDEX(ADMIN!$K$5:$DX$300,296,ADMIN!$D$5*3+8)
Name Rango_Admin_DailyPred_Primera: INDEX(ADMIN!$K$5:$DX$300,1,1):INDEX(ADMIN!$K$5:$DX$300,1,ADMIN!$D$5*3+8)

Sheet Home
B3: =Idiomas!D8 -> XXIII Mundial USA/MEX/CAN 2026
C5: ="📋 "&Idiomas!D7 -> 📋 Selecciona idioma
C6: Español | K6: Admin
C7: ="🕒 "&Idiomas!D15 -> 🕒 Selecciona horario
C8: UTC -4 | K8: =Idiomas!D4 -> Introducir resultados
C9: ="✍️ "&Idiomas!D48 -> ✍️ Escribe el nombre del grupo
C10: Inter | K10: Help
K12: =HYPERLINK(Idiomas!D302,Idiomas!D431) -> Sistema de puntuación
K14: =HYPERLINK(Idiomas!D13,"FAQ") -> FAQ
K17: Video►Tutorial
G19: =IFERROR(IF(E41<E42,Idiomas!D505,IF(AND(E41>=E42,E41<=E43),Idiomas!D507,""))&" "&IF(E41<E42,DATEDIF(E41,E42,"D"),IF(E41=E42,1,IF(AND(E41>E42,E41<=E43),DATEDIF(E42,E41,"D")+1,IF(E41>E43,"",""))))&" "&IF(E41<E42,Idiomas!D506,IF(AND(E41>=E42,E41<=E43),Idiomas!D508,"")),"") -> Es el día 1 del Mundial 2026
G20: =IFERROR(IF(E41<E42,"",IF(AND(E41>=E42,E41<=E43),Idiomas!D509,IF(E41>E43,"",)))&" "&IF(E41<E42,"",IF(AND(E41>=E42,E41<=E43),DATEDIF(E41,E43,"D"),IF(E41>E43,"",)))&" "&IF(E41<E42,"",IF(AND(E41>=E42,E41<=E43),Idiomas!D510,IF(E41>E43,"",))),"") -> Quedan 38 días para que acabe el Mundial 2026
E21: Share:
C22: 25 | E22: Whatsapp | F22: Telegram | G22: Mail | H22: X | I22: in
K23: © Miguel Angel Tejero. 2026
E41: =TODAY() -> 46184
E42: =INT(Horarios!C4) -> 46184
E43: =INT(Horarios!C147) -> 46222

Sheet WORLDCUP
W1: =Idiomas!D8 -> XXIII Mundial USA/MEX/CAN 2026 | AV1: Video►Tutorial | DN1: Horarios!$P$3
D3: WINNER | E3: Empate1L | F3: Empate1V | H3: Empate2L | I3: Empate2V | K3: Empate3L | L3: Empate3V | N3: Empate4L | O3: Empate4V | Q3: Empate5L | R3: Empate5V | T3: Empate6L | U3: Empate6V | X3: =Idiomas!D16 -> Fecha | Y3: =Idiomas!D17 -> Hora | Z3: =Idiomas!D18 -> Jor. | AA3: =Idiomas!D19 -> Casa | AC3: =Idiomas!D20 -> Gol | AD3: =Idiomas!D20 -> Gol | AF3: =Idiomas!D21 -> Fuera | AJ3: =Idiomas!D22 -> Grupo | AV3: =Idiomas!D23 -> ¡EMPATE! Puedes seleccionar el orden de los empatados. | AY3: =Idiomas!D74 -> ¿Hay equipos penalizados? | AZ3: No | DT3: Esta esta solo en admin para calculo de fechas en prediccion y clas diaria
A4: NombreEquipo | B4: A | C4: =COUNTIF(Equipos!$C$2:$C$49,WORLDCUP!B4) -> 4 | D4: =IF(OR(AC4="",AD4=""),"Pendiente",IF(AC4>AD4,"Local",IF(AC4<AD4,"Visitante","Empate"))) -> Pendiente | E4: =IF(D4="Pendiente","-",INDEX($BT$6:$BT$53,MATCH($AA4,$BD$6:$BD$53,0))) -> - | F4: =IF(D4="Pendiente","-",INDEX($BT$6:$BT$53,MATCH($AF4,$BD$6:$BD$53,0))) -> - | H4: =IF(D4="Pendiente","-",INDEX($BZ$6:$BZ$53,MATCH($AA4,$BD$6:$BD$53,0))) -> - | I4: =IF(D4="Pendiente","-",INDEX($BZ$6:$BZ$53,MATCH($AF4,$BD$6:$BD$53,0))) -> - | K4: =IF(D4="Pendiente","-",INDEX($CE$6:$CE$53,MATCH($AA4,$BD$6:$BD$53,0))) -> - | L4: =IF(D4="Pendiente","-",INDEX($CE$6:$CE$53,MATCH($AF4,$BD$6:$BD$53,0))) -> - | N4: =IF(D4="Pendiente","-",INDEX($CH$6:$CH$53,MATCH($AA4,$BD$6:$BD$53,0))) -> - | O4: =IF(D4="Pendiente","-",INDEX($CH$6:$CH$53,MATCH($AF4,$BD$6:$BD$53,0))) -> - | Q4: =IF(D4="Pendiente","-",INDEX($CN$6:$CN$53,MATCH($AA4,$BD$6:$BD$53,0))) -> - | R4: =IF(D4="Pendiente","-",INDEX($CN$6:$CN$53,MATCH($AF4,$BD$6:$BD$53,0))) -> - | T4: =IF(D4="Pendiente","-",INDEX($CS$6:$CS$53,MATCH($AA4,$BD$6:$BD$53,0))) -> - | U4: =IF(D4="Pendiente","-",INDEX($CS$6:$CS$53,MATCH($AF4,$BD$6:$BD$53,0))) -> - | W4: A | X4: =Horarios!C4 -> 46184.625 | Y4: =Horarios!C4 -> 46184.625 | Z4: =Idiomas!D63 -> J1 | AA4: =+A5 -> México | AB4: {=Ver_flag_local} | AC4: 2 | AD4: 0 | AE4: {=Ver_flag_visit} | AF4: =A6 -> Sudáfrica | AG4: =IF(NOT(OR(ISBLANK(AC4),ISBLANK(AD4))),1,0) -> 0 | AH4: 1 | AJ4: =CONCATENATE(AJ3," ",B4) -> Grupo A | AV4: =IF(AU5>0,$AV$3,"") | DC4: En Grupos por bombo, en terceros por orden alfa | DT4: =AA4&"-"&AF4 -> México-Sudáfrica
A5: =+Equipos!B2 -> México | D5: =IF(OR(AC5="",AD5=""),"Pendiente",IF(AC5>AD5,"Local",IF(AC5<AD5,"Visitante","Empate"))) -> Pendiente | E5: =IF(D5="Pendiente","-",INDEX($BT$6:$BT$53,MATCH($AA5,$BD$6:$BD$53,0))) -> - | F5: =IF(D5="Pendiente","-",INDEX($BT$6:$BT$53,MATCH($AF5,$BD$6:$BD$53,0))) -> - | H5: =IF(D5="Pendiente","-",INDEX($BZ$6:$BZ$53,MATCH($AA5,$BD$6:$BD$53,0))) -> - | I5: =IF(D5="Pendiente","-",INDEX($BZ$6:$BZ$53,MATCH($AF5,$BD$6:$BD$53,0))) -> - | K5: =IF(D5="Pendiente","-",INDEX($CE$6:$CE$53,MATCH($AA5,$BD$6:$BD$53,0))) -> - | L5: =IF(D5="Pendiente","-",INDEX($CE$6:$CE$53,MATCH($AF5,$BD$6:$BD$53,0))) -> - | N5: =IF(D5="Pendiente","-",INDEX($CH$6:$CH$53,MATCH($AA5,$BD$6:$BD$53,0))) -> - | O5: =IF(D5="Pendiente","-",INDEX($CH$6:$CH$53,MATCH($AF5,$BD$6:$BD$53,0))) -> - | Q5: =IF(D5="Pendiente","-",INDEX($CN$6:$CN$53,MATCH($AA5,$BD$6:$BD$53,0))) -> - | R5: =IF(D5="Pendiente","-",INDEX($CN$6:$CN$53,MATCH($AF5,$BD$6:$BD$53,0))) -> - | T5: =IF(D5="Pendiente","-",INDEX($CS$6:$CS$53,MATCH($AA5,$BD$6:$BD$53,0))) -> - | U5: =IF(D5="Pendiente","-",INDEX($CS$6:$CS$53,MATCH($AF5,$BD$6:$BD$53,0))) -> - | X5: =Horarios!C5 -> 46184.917 | Y5: =Horarios!C5 -> 46184.917 | Z5: =$Z$4 -> J1 | AA5: =A7 -> Corea del Sur | AB5: {=Ver_flag_local} | AE5: {=Ver_flag_visit} | AF5: =A8 -> República Checa | AG5: =IF(NOT(OR(ISBLANK(AC5),ISBLANK(AD5))),1,0) -> 0 | AH5: 2 | AJ5: =Idiomas!D53 -> Pos | AL5: =Idiomas!D54 -> Selección | AM5: =Idiomas!D55 -> Pts | AN5: =Idiomas!D56 -> J | AO5: =Idiomas!D57 -> G | AP5: =Idiomas!D58 -> E | AQ5: =Idiomas!D59 -> P | AR5: =Idiomas!D60 -> GF | AS5: =Idiomas!D61 -> GC | AT5: =Idiomas!D62 -> DG | AU5: =COUNTIF(AU6:AU9,">1") -> 0 | AY5: =AL5 -> Selección | AZ5: =+Idiomas!$D$69 -> Puntos penalizados | BC5: =Idiomas!D22 -> Grupo | BD5: =Idiomas!D54 -> Selección | BE5: =+AM5 -> Pts | BF5: =+AN5 -> J | BG5: =+AO5 -> G | BH5: =+AP5 -> E | BI5: =+AQ5 -> P | BJ5: =+AR5 -> GF | BK5: =+AS5 -> GC | BL5: =+AT5 -> DG | BM5: PosF1 | BN5: PosF3 | BO5: Participa | BP5: Pos0 | BQ5: Empate0 | BR5: PTS | BS5: Posicion1 | BT5: Empate1 | BU5: PGPart1 | BV5: PEPart1 | BW5: PPPart1 | BX5: PTSPart1 | BY5: Posicion2 | BZ5: Empate2 | CA5: GFPart1 | CB5: GCPart1 | CC5: DGPArt1 | CD5: Posicion3 | CE5: Empate3 | CF5: GFPart1 | CG5: Posicion4 | CH5: Empate4 | CI5: PGPart2 | CJ5: PEPart2 | CK5: PPPart2 | CL5: PTSPart2 | CM5: Posicion5 | CN5: Empate5 | CO5: GFPart2 | CP5: GCPart2 | CQ5: DGPArt2 | CR5: Posicion6 | CS5: Empate6 | CT5: GFPart2 | CU5: Posicion7 | CV5: Empate7 | CW5: DG | CX5: Posicion8 | CY5: Empate8 | CZ5: GF | DA5: Posicion9 | DB5: Empate9 | DC5: OrdenAlfa/Bombo | DD5: PosicionF1 | DF5: PosicionF2 | DG5: Criterio/Fila | DH5: PosicionF3 | DJ5: POS | DK5: Numero Partidos disputados grupo | DL5: CANT | DM5: CONCAT | DN5: DESEMPATE EN SELECTOR | DP5: POSGRUPO | DQ5: PAIS | DT5: =AA5&"-"&AF5 -> Corea del Sur-República Checa
A6: =+Equipos!B3 -> Sudáfrica | D6: =IF(OR(AC6="",AD6=""),"Pendiente",IF(AC6>AD6,"Local",IF(AC6<AD6,"Visitante","Empate"))) -> Pendiente | E6: =IF(D6="Pendiente","-",INDEX($BT$6:$BT$53,MATCH($AA6,$BD$6:$BD$53,0))) -> - | F6: =IF(D6="Pendiente","-",INDEX($BT$6:$BT$53,MATCH($AF6,$BD$6:$BD$53,0))) -> - | H6: =IF(D6="Pendiente","-",INDEX($BZ$6:$BZ$53,MATCH($AA6,$BD$6:$BD$53,0))) -> - | I6: =IF(D6="Pendiente","-",INDEX($BZ$6:$BZ$53,MATCH($AF6,$BD$6:$BD$53,0))) -> - | K6: =IF(D6="Pendiente","-",INDEX($CE$6:$CE$53,MATCH($AA6,$BD$6:$BD$53,0))) -> - | L6: =IF(D6="Pendiente","-",INDEX($CE$6:$CE$53,MATCH($AF6,$BD$6:$BD$53,0))) -> - | N6: =IF(D6="Pendiente","-",INDEX($CH$6:$CH$53,MATCH($AA6,$BD$6:$BD$53,0))) -> - | O6: =IF(D6="Pendiente","-",INDEX($CH$6:$CH$53,MATCH($AF6,$BD$6:$BD$53,0))) -> - | Q6: =IF(D6="Pendiente","-",INDEX($CN$6:$CN$53,MATCH($AA6,$BD$6:$BD$53,0))) -> - | R6: =IF(D6="Pendiente","-",INDEX($CN$6:$CN$53,MATCH($AF6,$BD$6:$BD$53,0))) -> - | T6: =IF(D6="Pendiente","-",INDEX($CS$6:$CS$53,MATCH($AA6,$BD$6:$BD$53,0))) -> - | U6: =IF(D6="Pendiente","-",INDEX($CS$6:$CS$53,MATCH($AF6,$BD$6:$BD$53,0))) -> - | X6: =Horarios!C6 -> 46191.5 | Y6: =Horarios!C6 -> 46191.5 | Z6: =Idiomas!D64 -> J2 | AA6: =A8 -> República Checa | AB6: {=Ver_flag_local} | AE6: {=Ver_flag_visit} | AF6: =A6 -> Sudáfrica | AG6: =IF(NOT(OR(ISBLANK(AC6),ISBLANK(AD6))),1,0) -> 0 | AH6: 25 | AI6: =AJ6&$B$4 -> 1A | AJ6: 1 | AK6: {=Ver_flag_visit} | AL6: =IFERROR(INDEX($BD$6:$BD$53,MATCH(AI6,$BN$6:$BN$53,0)),"") -> México | AM6: =INDEX($BE$6:$BN$53,MATCH($AL6,$BD$6:$BD$53,0),MATCH(AM$5,$BE$5:$BN$5,0)) -> 0 | AN6: =INDEX($BE$6:$BN$53,MATCH($AL6,$BD$6:$BD$53,0),MATCH(AN$5,$BE$5:$BN$5,0)) -> 0 | AO6: =INDEX($BE$6:$BN$53,MATCH($AL6,$BD$6:$BD$53,0),MATCH(AO$5,$BE$5:$BN$5,0)) -> 0 | AP6: =INDEX($BE$6:$BN$53,MATCH($AL6,$BD$6:$BD$53,0),MATCH(AP$5,$BE$5:$BN$5,0)) -> 0 | AQ6: =INDEX($BE$6:$BN$53,MATCH($AL6,$BD$6:$BD$53,0),MATCH(AQ$5,$BE$5:$BN$5,0)) -> 0 | AR6: =INDEX($BE$6:$BN$53,MATCH($AL6,$BD$6:$BD$53,0),MATCH(AR$5,$BE$5:$BN$5,0)) -> 0 | AS6: =INDEX($BE$6:$BN$53,MATCH($AL6,$BD$6:$BD$53,0),MATCH(AS$5,$BE$5:$BN$5,0)) -> 0 | AT6: =INDEX($BE$6:$BN$53,MATCH($AL6,$BD$6:$BD$53,0),MATCH(AT$5,$BE$5:$BN$5,0)) -> 0 | AU6: =INDEX($DL$6:$DL$53,MATCH(AI6,$DP$6:$DP$53,0)) -> 1 | AV6: =INDEX($BD$6:$BD$53,MATCH(AI6,$BM$6:$BM$53,0)) -> México | AY6: =+A5 -> México | BC6: =+INDEX(T_Equipos[Grupo],MATCH(WORLDCUP!BD6,T_Equipos[NombreEquipo],0)) -> A | BD6: =+Equipos!B2 -> México | BE6: =+BG6*3+BH6+IF($AZ$3="no",0,INDEX($AZ$6:$AZ$97,MATCH(BD6,$AY$6:$AY$97,0))) -> 0 | BF6: =+BG6+BH6+BI6 -> 0 | BG6: =+COUNTIFS(FGLocal,BD6,Ganador,"Local")+COUNTIFS(FGVisitante,BD6,Ganador,"Visitante") -> 0 | BH6: =+COUNTIFS(FGLocal,BD6,Ganador,"Empate")+COUNTIFS(FGVisitante,BD6,Ganador,"Empate") -> 0 | BI6: =+COUNTIFS(FGVisitante,BD6,Ganador,"Local")+COUNTIFS(FGLocal,BD6,Ganador,"Visitante") -> 0 | BJ6: =+SUMIFS(FG_GolesLocal,FGLocal,BD6,Ganador,"<>"&"Pendiente",FG_GolesLocal,"<>"&"",FG_GolesVisitante,"<>"&"")+SUMIFS(FG_GolesVisitante,FGVisitante,BD6,Ganador,"<>"&"Pendiente",FG_GolesLocal,"<>"&"",FG_GolesVisitante,"<>"&"") -> 0 | BK6: =+SUMIFS(FG_GolesLocal,FGVisitante,BD6,Ganador,"<>"&"Pendiente",FG_GolesLocal,"<>"&"",FG_GolesVisitante,"<>"&"")+SUMIFS(FG_GolesVisitante,FGLocal,BD6,Ganador,"<>"&"Pendiente",FG_GolesLocal,"<>"&"",FG_GolesVisitante,"<>"&"") -> 0 | BL6: =+BJ6-BK6 -> 0 | BM6: =DD6&BC6 -> 1A | BN6: =DH6&BC6 -> 1A | BO6: =IF(AND($AJ$99=144,BF6>=1),1,0) -> 0 | BP6: =COUNTIFS($BO$6:$BO$53,">"&BO6,$BC$6:$BC$53,INDEX(T_Equipos[Grupo],MATCH(BD6,T_Equipos[NombreEquipo],0)))+1 -> 1 | BQ6: =IF(COUNTIFS($BP$6:$BP$53,BP6,$BC$6:$BC$53,INDEX(T_Equipos[Grupo],MATCH(BD6,T_Equipos[NombreEquipo],0)))=1,"-","P."&BP6&" ("&COUNTIFS($BP$6:$BP$53,BP6,$BC$6:$BC$53,INDEX(T_Equipos[Grupo],MATCH(BD6,T_Equipos[NombreEquipo],0)))&")") -> P.1 (4) | BR6: =IF($BQ6="-","-",BE6) -> 0 | BS6: =BP6+COUNTIFS($BQ$6:$BQ$53,BQ6,$BR$6:BR$53,">"&BR6,$BC$6:$BC$53,INDEX(T_Equipos[Grupo],MATCH(BD6,T_Equipos[NombreEquipo],0))) -> 1 | BT6: =IF(COUNTIFS($BS$6:$BS$53,BS6,$BC$6:$BC$53,INDEX(T_Equipos[Grupo],MATCH(BD6,T_Equipos[NombreEquipo],0)))=1,"-","P."&BS6&" ("&COUNTIFS($BS$6:$BS$53,BS6,$BC$6:$BC$53,INDEX(T_Equipos[Grupo],MATCH(BD6,T_Equipos[NombreEquipo],0)))&")") -> P.1 (4) | BU6: =IF($BT6="-","-",COUNTIFS(FGLocal,$BD6,Ganador,"Local",Part1Empate1V,$BT6)+COUNTIFS(FGVisitante,$BD6,Ganador,"Visitante",Part1Empate1L,$BT6)) -> 0 | BV6: =IF($BT6="-","-",COUNTIFS(FGLocal,$BD6,Ganador,"Empate",Part1Empate1V,$BT6)+COUNTIFS(FGVisitante,$BD6,Ganador,"Empate",Part1Empate1L,$BT6)) -> 0 | BW6: =IF($BT6="-","-",COUNTIFS(FGLocal,$BD6,Ganador,"Visitante",Part1Empate1V,$BT6)+COUNTIFS(FGVisitante,$BD6,Ganador,"Local",Part1Empate1L,$BT6)) -> 0 | BX6: =IF($BT6="-","-",BU6*3+BV6) -> 0 | BY6: =BS6+COUNTIFS($BT$6:$BT$53,BT6,$BX$6:BX$53,">"&BX6,$BC$6:$BC$53,INDEX(T_Equipos[Grupo],MATCH(BD6,T_Equipos[NombreEquipo],0))) -> 1 | BZ6: =IF(COUNTIFS($BY$6:$BY$53,BY6,$BC$6:$BC$53,INDEX(T_Equipos[Grupo],MATCH(BD6,T_Equipos[NombreEquipo],0)))=1,"-","P."&BY6&" ("&COUNTIFS($BY$6:$BY$53,BY6,$BC$6:$BC$53,INDEX(T_Equipos[Grupo],MATCH(BD6,T_Equipos[NombreEquipo],0)))&")") -> P.1 (4) | CA6: =IF($BZ6="-","-",SUMIFS(FG_GolesLocal,FGLocal,$BD6,Part1Empate2V,$BZ6)+SUMIFS(FG_GolesVisitante,FGVisitante,$BD6,Part1Empate2L,$BZ6)) -> 0 | CB6: =IF($BZ6="-","-",SUMIFS(FG_GolesVisitante,FGLocal,$BD6,Part1Empate2V,$BZ6)+SUMIFS(FG_GolesLocal,FGVisitante,$BD6,Part1Empate2L,$BZ6)) -> 0 | CC6: =IF($BZ6="-","-",CA6-CB6) -> 0 | CD6: =BY6+COUNTIFS($BZ$6:$BZ$53,BZ6,$CC$6:CC$53,">"&CC6,$BC$6:$BC$53,INDEX(T_Equipos[Grupo],MATCH(BD6,T_Equipos[NombreEquipo],0))) -> 1 | CE6: =IF(COUNTIFS($CD$6:$CD$53,CD6,$BC$6:$BC$53,INDEX(T_Equipos[Grupo],MATCH(BD6,T_Equipos[NombreEquipo],0)))=1,"-","P."&CD6&" ("&COUNTIFS($CD$6:$CD$53,CD6,$BC$6:$BC$53,INDEX(T_Equipos[Grupo],MATCH(BD6,T_Equipos[NombreEquipo],0)))&")") -> P.1 (4) | CF6: =IF($CE6="-","-",SUMIFS(FG_GolesLocal,FGLocal,$BD6,Part1Empate3V,$CE6)+SUMIFS(FG_GolesVisitante,FGVisitante,$BD6,Part1Empate3L,$CE6)) -> 0 | CG6: =CD6+COUNTIFS($CE$6:$CE$53,CE6,$CF$6:CF$53,">"&CF6,$BC$6:$BC$53,INDEX(T_Equipos[Grupo],MATCH(BD6,T_Equipos[NombreEquipo],0))) -> 1 | CH6: =IF(COUNTIFS($CG$6:$CG$53,CG6,$BC$6:$BC$53,INDEX(T_Equipos[Grupo],MATCH(BD6,T_Equipos[NombreEquipo],0)))=1,"-","P."&CG6&" ("&COUNTIFS($CG$6:$CG$53,CG6,$BC$6:$BC$53,INDEX(T_Equipos[Grupo],MATCH(BD6,T_Equipos[NombreEquipo],0)))&")") -> P.1 (4) | CI6: =IF($CH6="-","-",COUNTIFS(FGLocal,$BD6,Ganador,"Local",Part2Empate4V,$CH6)+COUNTIFS(FGVisitante,$BD6,Ganador,"Visitante",Part2Empate4L,$CH6)) -> 0 | CJ6: =IF($CH6="-","-",COUNTIFS(FGLocal,$BD6,Ganador,"Empate",Part2Empate4V,$CH6)+COUNTIFS(FGVisitante,$BD6,Ganador,"Empate",Part2Empate4L,$CH6)) -> 0 | CK6: =IF($CH6="-","-",COUNTIFS(FGLocal,$BD6,Ganador,"Visitante",Part2Empate4V,$CH6)+COUNTIFS(FGVisitante,$BD6,Ganador,"Local",Part2Empate4L,$CH6)) -> 0 | CL6: =IF($CH6="-","-",CI6*3+CJ6) -> 0 | CM6: =CG6+COUNTIFS($CH$6:$CH$53,CH6,$CL$6:CL$53,">"&CL6,$BC$6:$BC$53,INDEX(T_Equipos[Grupo],MATCH(BD6,T_Equipos[NombreEquipo],0))) -> 1 | CN6: =IF(COUNTIFS($CM$6:$CM$53,CM6,$BC$6:$BC$53,INDEX(T_Equipos[Grupo],MATCH(BD6,T_Equipos[NombreEquipo],0)))=1,"-","P."&CM6&" ("&COUNTIFS($CM$6:$CM$53,CM6,$BC$6:$BC$53,INDEX(T_Equipos[Grupo],MATCH(BD6,T_Equipos[NombreEquipo],0)))&")") -> P.1 (4) | CO6: =IF($CN6="-","-",SUMIFS(FG_GolesLocal,FGLocal,$BD6,Part2Empate5V,$CN6)+SUMIFS(FG_GolesVisitante,FGVisitante,$BD6,Part2Empate5L,$CN6)) -> 0 | CP6: =IF($CN6="-","-",SUMIFS(FG_GolesVisitante,FGLocal,$BD6,Part2Empate5V,$CN6)+SUMIFS(FG_GolesLocal,FGVisitante,$BD6,Part2Empate5L,$CN6)) -> 0 | CQ6: =IF($CN6="-","-",CO6-CP6) -> 0 | CR6: =CM6+COUNTIFS($CN$6:$CN$53,CN6,$CQ$6:CQ$53,">"&CQ6,$BC$6:$BC$53,INDEX(T_Equipos[Grupo],MATCH(BD6,T_Equipos[NombreEquipo],0))) -> 1 | CS6: =IF(COUNTIFS($CR$6:$CR$53,CR6,$BC$6:$BC$53,INDEX(T_Equipos[Grupo],MATCH(BD6,T_Equipos[NombreEquipo],0)))=1,"-","P."&CR6&" ("&COUNTIFS($CR$6:$CR$53,CR6,$BC$6:$BC$53,INDEX(T_Equipos[Grupo],MATCH(BD6,T_Equipos[NombreEquipo],0)))&")") -> P.1 (4) | CT6: =IF($CS6="-","-",SUMIFS(FG_GolesLocal,FGLocal,$BD6,Part2Empate6V,$CS6)+SUMIFS(FG_GolesVisitante,FGVisitante,$BD6,Part2Empate6L,$CS6)) -> 0 | CU6: =CR6+COUNTIFS($CS$6:$CS$53,CS6,$CT$6:CT$53,">"&CT6,$BC$6:$BC$53,INDEX(T_Equipos[Grupo],MATCH(BD6,T_Equipos[NombreEquipo],0))) -> 1 | CV6: =IF(COUNTIFS($CU$6:$CU$53,CU6,$BC$6:$BC$53,INDEX(T_Equipos[Grupo],MATCH(BD6,T_Equipos[NombreEquipo],0)))=1,"-","P."&CU6&" ("&COUNTIFS($CU$6:$CU$53,CU6,$BC$6:$BC$53,INDEX(T_Equipos[Grupo],MATCH(BD6,T_Equipos[NombreEquipo],0)))&")") -> P.1 (4) | CW6: =IF(CV6="-","-",BL6) -> 0 | CX6: =CU6+COUNTIFS($CV$6:$CV$53,CV6,$CW$6:CW$53,">"&CW6,$BC$6:$BC$53,INDEX(T_Equipos[Grupo],MATCH(BD6,T_Equipos[NombreEquipo],0))) -> 1 | CY6: =IF(COUNTIFS($CX$6:$CX$53,CX6,$BC$6:$BC$53,INDEX(T_Equipos[Grupo],MATCH(BD6,T_Equipos[NombreEquipo],0)))=1,"-","P."&CX6&" ("&COUNTIFS($CX$6:$CX$53,CX6,$BC$6:$BC$53,INDEX(T_Equipos[Grupo],MATCH(BD6,T_Equipos[NombreEquipo],0)))&")") -> P.1 (4) | CZ6: =IF(CY6="-","-",BJ6) -> 0 | DA6: =CX6+COUNTIFS($CY$6:$CY$53,CY6,$CZ$6:CZ$53,">"&CZ6,$BC$6:$BC$53,INDEX(T_Equipos[Grupo],MATCH(BD6,T_Equipos[NombreEquipo],0))) -> 1 | DB6: =IF(COUNTIFS($DA$6:$DA$53,DA6,$BC$6:$BC$53,INDEX(T_Equipos[Grupo],MATCH(BD6,T_Equipos[NombreEquipo],0)))=1,"-","P."&DA6&" ("&COUNTIFS($DA$6:$DA$53,DA6,$BC$6:$BC$53,INDEX(T_Equipos[Grupo],MATCH(BD6,T_Equipos[NombreEquipo],0)))&")") -> P.1 (4) | DC6: =IF(DB6="-","-",COUNTIFS(T_Equipos[Rank],"<"&INDEX(T_Equipos[Rank],MATCH(BD6,T_Equipos[NombreEquipo],0)),$BC$6:$BC$53,INDEX(T_Equipos[Grupo],MATCH(BD6,T_Equipos[NombreEquipo],0)))+1) -> 1 | DD6: =DA6+COUNTIFS($DB$6:$DB$53,DB6,$DC$6:DC$53,"<"&DC6,$BC$6:$BC$53,INDEX(T_Equipos[Grupo],MATCH(BD6,T_Equipos[NombreEquipo],0))) -> 1 | DF6: =IF(OR(INDEX($AW$6:$AW$97,MATCH($BD6,$AV$6:$AV$97,0))="",DB6="-"),DD6,INDEX($AW$6:$AW$97,MATCH($BD6,$AV$6:$AV$97,0))+DD6/1000) -> 1 | DG6: =IF(DB6="-","-",COUNTIFS(DF$6:DF$53,"<"&DF6,$BC$6:$BC$53,INDEX(T_Equipos[Grupo],MATCH(BD6,T_Equipos[NombreEquipo],0)))) -> 0 | DH6: =DA6+COUNTIFS(DB$6:DB$53,DB6,DG$6:DG$53,"<"&DG6,$BC$6:$BC$53,INDEX(T_Equipos[Grupo],MATCH(BD6,T_Equipos[NombreEquipo],0))) -> 1 | DJ6: =INDEX($DA$6:$DA$53,MATCH($DQ6,$BD$6:$BD$53,0)) -> 1 | DK6: =+SUMIF($BC$6:$BC$53,BC6,$BF$6:$BF$53) -> 0 | DL6: =IF(OR(DK6=12,$AJ$99=144),COUNTIFS($DJ$6:$DJ$53,DJ6,$BC$6:$BC$53,BC6),1) -> 1 | DM6: =DJ6&"."&DL6 -> 1.1 | DN6: {=OFFSET(Horarios!$P$3,DJ6-1,0,DL6,1)} -> 1 | DP6: 1A | DQ6: =INDEX($BD$6:$BD$53,MATCH(DP6,$BM$6:$BM$53,0)) -> México | DT6: =AA6&"-"&AF6 -> República Checa-Sudáfrica
A7: =+Equipos!B4 -> Corea del Sur | D7: =IF(OR(AC7="",AD7=""),"Pendiente",IF(AC7>AD7,"Local",IF(AC7<AD7,"Visitante","Empate"))) -> Pendiente | E7: =IF(D7="Pendiente","-",INDEX($BT$6:$BT$53,MATCH($AA7,$BD$6:$BD$53,0))) -> - | F7: =IF(D7="Pendiente","-",INDEX($BT$6:$BT$53,MATCH($AF7,$BD$6:$BD$53,0))) -> - | H7: =IF(D7="Pendiente","-",INDEX($BZ$6:$BZ$53,MATCH($AA7,$BD$6:$BD$53,0))) -> - | I7: =IF(D7="Pendiente","-",INDEX($BZ$6:$BZ$53,MATCH($AF7,$BD$6:$BD$53,0))) -> - | K7: =IF(D7="Pendiente","-",INDEX($CE$6:$CE$53,MATCH($AA7,$BD$6:$BD$53,0))) -> - | L7: =IF(D7="Pendiente","-",INDEX($CE$6:$CE$53,MATCH($AF7,$BD$6:$BD$53,0))) -> - | N7: =IF(D7="Pendiente","-",INDEX($CH$6:$CH$53,MATCH($AA7,$BD$6:$BD$53,0))) -> - | O7: =IF(D7="Pendiente","-",INDEX($CH$6:$CH$53,MATCH($AF7,$BD$6:$BD$53,0))) -> - | Q7: =IF(D7="Pendiente","-",INDEX($CN$6:$CN$53,MATCH($AA7,$BD$6:$BD$53,0))) -> - | R7: =IF(D7="Pendiente","-",INDEX($CN$6:$CN$53,MATCH($AF7,$BD$6:$BD$53,0))) -> - | T7: =IF(D7="Pendiente","-",INDEX($CS$6:$CS$53,MATCH($AA7,$BD$6:$BD$53,0))) -> - | U7: =IF(D7="Pendiente","-",INDEX($CS$6:$CS$53,MATCH($AF7,$BD$6:$BD$53,0))) -> - | X7: =Horarios!C7 -> 46191.875 | Y7: =Horarios!C7 -> 46191.875 | Z7: =$Z$6 -> J2 | AA7: =A5 -> México | AB7: {=Ver_flag_local} | AE7: {=Ver_flag_visit} | AF7: =A7 -> Corea del Sur | AG7: =IF(NOT(OR(ISBLANK(AC7),ISBLANK(AD7))),1,0) -> 0 | AH7: 28 | AI7: =AJ7&$B$4 -> 2A | AJ7: 2 | AK7: {=Ver_flag_visit} | AL7: =IFERROR(INDEX($BD$6:$BD$53,MATCH(AI7,$BN$6:$BN$53,0)),"") -> Sudáfrica | AM7: =INDEX($BE$6:$BN$53,MATCH($AL7,$BD$6:$BD$53,0),MATCH(AM$5,$BE$5:$BN$5,0)) -> 0 | AN7: =INDEX($BE$6:$BN$53,MATCH($AL7,$BD$6:$BD$53,0),MATCH(AN$5,$BE$5:$BN$5,0)) -> 0 | AO7: =INDEX($BE$6:$BN$53,MATCH($AL7,$BD$6:$BD$53,0),MATCH(AO$5,$BE$5:$BN$5,0)) -> 0 | AP7: =INDEX($BE$6:$BN$53,MATCH($AL7,$BD$6:$BD$53,0),MATCH(AP$5,$BE$5:$BN$5,0)) -> 0 | AQ7: =INDEX($BE$6:$BN$53,MATCH($AL7,$BD$6:$BD$53,0),MATCH(AQ$5,$BE$5:$BN$5,0)) -> 0 | AR7: =INDEX($BE$6:$BN$53,MATCH($AL7,$BD$6:$BD$53,0),MATCH(AR$5,$BE$5:$BN$5,0)) -> 0 | AS7: =INDEX($BE$6:$BN$53,MATCH($AL7,$BD$6:$BD$53,0),MATCH(AS$5,$BE$5:$BN$5,0)) -> 0 | AT7: =INDEX($BE$6:$BN$53,MATCH($AL7,$BD$6:$BD$53,0),MATCH(AT$5,$BE$5:$BN$5,0)) -> 0 | AU7: =INDEX($DL$6:$DL$53,MATCH(AI7,$DP$6:$DP$53,0)) -> 1 | AV7: =INDEX($BD$6:$BD$53,MATCH(AI7,$BM$6:$BM$53,0)) -> Sudáfrica | AY7: =+A6 -> Sudáfrica | BC7: =+INDEX(T_Equipos[Grupo],MATCH(WORLDCUP!BD7,T_Equipos[NombreEquipo],0)) -> A | BD7: =+Equipos!B3 -> Sudáfrica | BE7: =+BG7*3+BH7+IF($AZ$3="no",0,INDEX($AZ$6:$AZ$97,MATCH(BD7,$AY$6:$AY$97,0))) -> 0 | BF7: =+BG7+BH7+BI7 -> 0 | BG7: =+COUNTIFS(FGLocal,BD7,Ganador,"Local")+COUNTIFS(FGVisitante,BD7,Ganador,"Visitante") -> 0 | BH7: =+COUNTIFS(FGLocal,BD7,Ganador,"Empate")+COUNTIFS(FGVisitante,BD7,Ganador,"Empate") -> 0 | BI7: =+COUNTIFS(FGVisitante,BD7,Ganador,"Local")+COUNTIFS(FGLocal,BD7,Ganador,"Visitante") -> 0 | BJ7: =+SUMIFS(FG_GolesLocal,FGLocal,BD7,Ganador,"<>"&"Pendiente",FG_GolesLocal,"<>"&"",FG_GolesVisitante,"<>"&"")+SUMIFS(FG_GolesVisitante,FGVisitante,BD7,Ganador,"<>"&"Pendiente",FG_GolesLocal,"<>"&"",FG_GolesVisitante,"<>"&"") -> 0 | BK7: =+SUMIFS(FG_GolesLocal,FGVisitante,BD7,Ganador,"<>"&"Pendiente",FG_GolesLocal,"<>"&"",FG_GolesVisitante,"<>"&"")+SUMIFS(FG_GolesVisitante,FGLocal,BD7,Ganador,"<>"&"Pendiente",FG_GolesLocal,"<>"&"",FG_GolesVisitante,"<>"&"") -> 0 | BL7: =+BJ7-BK7 -> 0 | BM7: =DD7&BC7 -> 2A | BN7: =DH7&BC7 -> 2A | BO7: =IF(AND($AJ$99=144,BF7>=1),1,0) -> 0 | BP7: =COUNTIFS($BO$6:$BO$53,">"&BO7,$BC$6:$BC$53,INDEX(T_Equipos[Grupo],MATCH(BD7,T_Equipos[NombreEquipo],0)))+1 -> 1 | BQ7: =IF(COUNTIFS($BP$6:$BP$53,BP7,$BC$6:$BC$53,INDEX(T_Equipos[Grupo],MATCH(BD7,T_Equipos[NombreEquipo],0)))=1,"-","P."&BP7&" ("&COUNTIFS($BP$6:$BP$53,BP7,$BC$6:$BC$53,INDEX(T_Equipos[Grupo],MATCH(BD7,T_Equipos[NombreEquipo],0)))&")") -> P.1 (4) | BR7: =IF($BQ7="-","-",BE7) -> 0 | BS7: =BP7+COUNTIFS($BQ$6:$BQ$53,BQ7,$BR$6:BR$53,">"&BR7,$BC$6:$BC$53,INDEX(T_Equipos[Grupo],MATCH(BD7,T_Equipos[NombreEquipo],0))) -> 1 | BT7: =IF(COUNTIFS($BS$6:$BS$53,BS7,$BC$6:$BC$53,INDEX(T_Equipos[Grupo],MATCH(BD7,T_Equipos[NombreEquipo],0)))=1,"-","P."&BS7&" ("&COUNTIFS($BS$6:$BS$53,BS7,$BC$6:$BC$53,INDEX(T_Equipos[Grupo],MATCH(BD7,T_Equipos[NombreEquipo],0)))&")") -> P.1 (4) | BU7: =IF($BT7="-","-",COUNTIFS(FGLocal,$BD7,Ganador,"Local",Part1Empate1V,$BT7)+COUNTIFS(FGVisitante,$BD7,Ganador,"Visitante",Part1Empate1L,$BT7)) -> 0 | BV7: =IF($BT7="-","-",COUNTIFS(FGLocal,$BD7,Ganador,"Empate",Part1Empate1V,$BT7)+COUNTIFS(FGVisitante,$BD7,Ganador,"Empate",Part1Empate1L,$BT7)) -> 0 | BW7: =IF($BT7="-","-",COUNTIFS(FGLocal,$BD7,Ganador,"Visitante",Part1Empate1V,$BT7)+COUNTIFS(FGVisitante,$BD7,Ganador,"Local",Part1Empate1L,$BT7)) -> 0 | BX7: =IF($BT7="-","-",BU7*3+BV7) -> 0 | BY7: =BS7+COUNTIFS($BT$6:$BT$53,BT7,$BX$6:BX$53,">"&BX7,$BC$6:$BC$53,INDEX(T_Equipos[Grupo],MATCH(BD7,T_Equipos[NombreEquipo],0))) -> 1 | BZ7: =IF(COUNTIFS($BY$6:$BY$53,BY7,$BC$6:$BC$53,INDEX(T_Equipos[Grupo],MATCH(BD7,T_Equipos[NombreEquipo],0)))=1,"-","P."&BY7&" ("&COUNTIFS($BY$6:$BY$53,BY7,$BC$6:$BC$53,INDEX(T_Equipos[Grupo],MATCH(BD7,T_Equipos[NombreEquipo],0)))&")") -> P.1 (4) | CA7: =IF($BZ7="-","-",SUMIFS(FG_GolesLocal,FGLocal,$BD7,Part1Empate2V,$BZ7)+SUMIFS(FG_GolesVisitante,FGVisitante,$BD7,Part1Empate2L,$BZ7)) -> 0 | CB7: =IF($BZ7="-","-",SUMIFS(FG_GolesVisitante,FGLocal,$BD7,Part1Empate2V,$BZ7)+SUMIFS(FG_GolesLocal,FGVisitante,$BD7,Part1Empate2L,$BZ7)) -> 0 | CC7: =IF($BZ7="-","-",CA7-CB7) -> 0 | CD7: =BY7+COUNTIFS($BZ$6:$BZ$53,BZ7,$CC$6:CC$53,">"&CC7,$BC$6:$BC$53,INDEX(T_Equipos[Grupo],MATCH(BD7,T_Equipos[NombreEquipo],0))) -> 1 | CE7: =IF(COUNTIFS($CD$6:$CD$53,CD7,$BC$6:$BC$53,INDEX(T_Equipos[Grupo],MATCH(BD7,T_Equipos[NombreEquipo],0)))=1,"-","P."&CD7&" ("&COUNTIFS($CD$6:$CD$53,CD7,$BC$6:$BC$53,INDEX(T_Equipos[Grupo],MATCH(BD7,T_Equipos[NombreEquipo],0)))&")") -> P.1 (4) | CF7: =IF($CE7="-","-",SUMIFS(FG_GolesLocal,FGLocal,$BD7,Part1Empate3V,$CE7)+SUMIFS(FG_GolesVisitante,FGVisitante,$BD7,Part1Empate3L,$CE7)) -> 0 | CG7: =CD7+COUNTIFS($CE$6:$CE$53,CE7,$CF$6:CF$53,">"&CF7,$BC$6:$BC$53,INDEX(T_Equipos[Grupo],MATCH(BD7,T_Equipos[NombreEquipo],0))) -> 1 | CH7: =IF(COUNTIFS($CG$6:$CG$53,CG7,$BC$6:$BC$53,INDEX(T_Equipos[Grupo],MATCH(BD7,T_Equipos[NombreEquipo],0)))=1,"-","P."&CG7&" ("&COUNTIFS($CG$6:$CG$53,CG7,$BC$6:$BC$53,INDEX(T_Equipos[Grupo],MATCH(BD7,T_Equipos[NombreEquipo],0)))&")") -> P.1 (4) | CI7: =IF($CH7="-","-",COUNTIFS(FGLocal,$BD7,Ganador,"Local",Part2Empate4V,$CH7)+COUNTIFS(FGVisitante,$BD7,Ganador,"Visitante",Part2Empate4L,$CH7)) -> 0 | CJ7: =IF($CH7="-","-",COUNTIFS(FGLocal,$BD7,Ganador,"Empate",Part2Empate4V,$CH7)+COUNTIFS(FGVisitante,$BD7,Ganador,"Empate",Part2Empate4L,$CH7)) -> 0 | CK7: =IF($CH7="-","-",COUNTIFS(FGLocal,$BD7,Ganador,"Visitante",Part2Empate4V,$CH7)+COUNTIFS(FGVisitante,$BD7,Ganador,"Local",Part2Empate4L,$CH7)) -> 0 | CL7: =IF($CH7="-","-",CI7*3+CJ7) -> 0 | CM7: =CG7+COUNTIFS($CH$6:$CH$53,CH7,$CL$6:CL$53,">"&CL7,$BC$6:$BC$53,INDEX(T_Equipos[Grupo],MATCH(BD7,T_Equipos[NombreEquipo],0))) -> 1 | CN7: =IF(COUNTIFS($CM$6:$CM$53,CM7,$BC$6:$BC$53,INDEX(T_Equipos[Grupo],MATCH(BD7,T_Equipos[NombreEquipo],0)))=1,"-","P."&CM7&" ("&COUNTIFS($CM$6:$CM$53,CM7,$BC$6:$BC$53,INDEX(T_Equipos[Grupo],MATCH(BD7,T_Equipos[NombreEquipo],0)))&")") -> P.1 (4) | CO7: =IF($CN7="-","-",SUMIFS(FG_GolesLocal,FGLocal,$BD7,Part2Empate5V,$CN7)+SUMIFS(FG_GolesVisitante,FGVisitante,$BD7,Part2Empate5L,$CN7)) -> 0 | CP7: =IF($CN7="-","-",SUMIFS(FG_GolesVisitante,FGLocal,$BD7,Part2Empate5V,$CN7)+SUMIFS(FG_GolesLocal,FGVisitante,$BD7,Part2Empate5L,$CN7)) -> 0 | CQ7: =IF($CN7="-","-",CO7-CP7) -> 0 | CR7: =CM7+COUNTIFS($CN$6:$CN$53,CN7,$CQ$6:CQ$53,">"&CQ7,$BC$6:$BC$53,INDEX(T_Equipos[Grupo],MATCH(BD7,T_Equipos[NombreEquipo],0))) -> 1 | CS7: =IF(COUNTIFS($CR$6:$CR$53,CR7,$BC$6:$BC$53,INDEX(T_Equipos[Grupo],MATCH(BD7,T_Equipos[NombreEquipo],0)))=1,"-","P."&CR7&" ("&COUNTIFS($CR$6:$CR$53,CR7,$BC$6:$BC$53,INDEX(T_Equipos[Grupo],MATCH(BD7,T_Equipos[NombreEquipo],0)))&")") -> P.1 (4) | CT7: =IF($CS7="-","-",SUMIFS(FG_GolesLocal,FGLocal,$BD7,Part2Empate6V,$CS7)+SUMIFS(FG_GolesVisitante,FGVisitante,$BD7,Part2Empate6L,$CS7)) -> 0 | CU7: =CR7+COUNTIFS($CS$6:$CS$53,CS7,$CT$6:CT$53,">"&CT7,$BC$6:$BC$53,INDEX(T_Equipos[Grupo],MATCH(BD7,T_Equipos[NombreEquipo],0))) -> 1 | CV7: =IF(COUNTIFS($CU$6:$CU$53,CU7,$BC$6:$BC$53,INDEX(T_Equipos[Grupo],MATCH(BD7,T_Equipos[NombreEquipo],0)))=1,"-","P."&CU7&" ("&COUNTIFS($CU$6:$CU$53,CU7,$BC$6:$BC$53,INDEX(T_Equipos[Grupo],MATCH(BD7,T_Equipos[NombreEquipo],0)))&")") -> P.1 (4) | CW7: =IF(CV7="-","-",BL7) -> 0 | CX7: =CU7+COUNTIFS($CV$6:$CV$53,CV7,$CW$6:CW$53,">"&CW7,$BC$6:$BC$53,INDEX(T_Equipos[Grupo],MATCH(BD7,T_Equipos[NombreEquipo],0))) -> 1 | CY7: =IF(COUNTIFS($CX$6:$CX$53,CX7,$BC$6:$BC$53,INDEX(T_Equipos[Grupo],MATCH(BD7,T_Equipos[NombreEquipo],0)))=1,"-","P."&CX7&" ("&COUNTIFS($CX$6:$CX$53,CX7,$BC$6:$BC$53,INDEX(T_Equipos[Grupo],MATCH(BD7,T_Equipos[NombreEquipo],0)))&")") -> P.1 (4) | CZ7: =IF(CY7="-","-",BJ7) -> 0 | DA7: =CX7+COUNTIFS($CY$6:$CY$53,CY7,$CZ$6:CZ$53,">"&CZ7,$BC$6:$BC$53,INDEX(T_Equipos[Grupo],MATCH(BD7,T_Equipos[NombreEquipo],0))) -> 1 | DB7: =IF(COUNTIFS($DA$6:$DA$53,DA7,$BC$6:$BC$53,INDEX(T_Equipos[Grupo],MATCH(BD7,T_Equipos[NombreEquipo],0)))=1,"-","P."&DA7&" ("&COUNTIFS($DA$6:$DA$53,DA7,$BC$6:$BC$53,INDEX(T_Equipos[Grupo],MATCH(BD7,T_Equipos[NombreEquipo],0)))&")") -> P.1 (4) | DC7: =IF(DB7="-","-",COUNTIFS(T_Equipos[Rank],"<"&INDEX(T_Equipos[Rank],MATCH(BD7,T_Equipos[NombreEquipo],0)),$BC$6:$BC$53,INDEX(T_Equipos[Grupo],MATCH(BD7,T_Equipos[NombreEquipo],0)))+1) -> 2 | DD7: =DA7+COUNTIFS($DB$6:$DB$53,DB7,$DC$6:DC$53,"<"&DC7,$BC$6:$BC$53,INDEX(T_Equipos[Grupo],MATCH(BD7,T_Equipos[NombreEquipo],0))) -> 2 | DF7: =IF(OR(INDEX($AW$6:$AW$97,MATCH($BD7,$AV$6:$AV$97,0))="",DB7="-"),DD7,INDEX($AW$6:$AW$97,MATCH($BD7,$AV$6:$AV$97,0))+DD7/1000) -> 2 | DG7: =IF(DB7="-","-",COUNTIFS(DF$6:DF$53,"<"&DF7,$BC$6:$BC$53,INDEX(T_Equipos[Grupo],MATCH(BD7,T_Equipos[NombreEquipo],0)))) -> 1 | DH7: =DA7+COUNTIFS(DB$6:DB$53,DB7,DG$6:DG$53,"<"&DG7,$BC$6:$BC$53,INDEX(T_Equipos[Grupo],MATCH(BD7,T_Equipos[NombreEquipo],0))) -> 2 | DJ7: =INDEX($DA$6:$DA$53,MATCH($DQ7,$BD$6:$BD$53,0)) -> 1 | DK7: =+SUMIF($BC$6:$BC$53,BC7,$BF$6:$BF$53) -> 0 | DL7: =IF(OR(DK7=12,$AJ$99=144),COUNTIFS($DJ$6:$DJ$53,DJ7,$BC$6:$BC$53,BC7),1) -> 1 | DM7: =DJ7&"."&DL7 -> 1.1 | DN7: {=OFFSET(Horarios!$P$3,DJ7-1,0,DL7,1)} -> 1 | DP7: 2A | DQ7: =INDEX($BD$6:$BD$53,MATCH(DP7,$BM$6:$BM$53,0)) -> Sudáfrica | DT7: =AA7&"-"&AF7 -> México-Corea del Sur
A8: =+Equipos!B5 -> República Checa | D8: =IF(OR(AC8="",AD8=""),"Pendiente",IF(AC8>AD8,"Local",IF(AC8<AD8,"Visitante","Empate"))) -> Pendiente | E8: =IF(D8="Pendiente","-",INDEX($BT$6:$BT$53,MATCH($AA8,$BD$6:$BD$53,0))) -> - | F8: =IF(D8="Pendiente","-",INDEX($BT$6:$BT$53,MATCH($AF8,$BD$6:$BD$53,0))) -> - | H8: =IF(D8="Pendiente","-",INDEX($BZ$6:$BZ$53,MATCH($AA8,$BD$6:$BD$53,0))) -> - | I8: =IF(D8="Pendiente","-",INDEX($BZ$6:$BZ$53,MATCH($AF8,$BD$6:$BD$53,0))) -> - | K8: =IF(D8="Pendiente","-",INDEX($CE$6:$CE$53,MATCH($AA8,$BD$6:$BD$53,0))) -> - | L8: =IF(D8="Pendiente","-",INDEX($CE$6:$CE$53,MATCH($AF8,$BD$6:$BD$53,0))) -> - | N8: =IF(D8="Pendiente","-",INDEX($CH$6:$CH$53,MATCH($AA8,$BD$6:$BD$53,0))) -> - | O8: =IF(D8="Pendiente","-",INDEX($CH$6:$CH$53,MATCH($AF8,$BD$6:$BD$53,0))) -> - | Q8: =IF(D8="Pendiente","-",INDEX($CN$6:$CN$53,MATCH($AA8,$BD$6:$BD$53,0))) -> - | R8: =IF(D8="Pendiente","-",INDEX($CN$6:$CN$53,MATCH($AF8,$BD$6:$BD$53,0))) -> - | T8: =IF(D8="Pendiente","-",INDEX($CS$6:$CS$53,MATCH($AA8,$BD$6:$BD$53,0))) -> - | U8: =IF(D8="Pendiente","-",INDEX($CS$6:$CS$53,MATCH($AF8,$BD$6:$BD$53,0))) -> - | X8: =Horarios!C8 -> 46197.875 | Y8: =Horarios!C8 -> 46197.875 | Z8: =Idiomas!D65 -> J3 | AA8: =A8 -> República Checa | AB8: {=Ver_flag_local} | AE8: {=Ver_flag_visit} | AF8: =A5 -> México | AG8: =IF(NOT(OR(ISBLANK(AC8),ISBLANK(AD8))),1,0) -> 0 | AH8: 53 | AI8: =AJ8&$B$4 -> 3A | AJ8: 3 | AK8: {=Ver_flag_visit} | AL8: =IFERROR(INDEX($BD$6:$BD$53,MATCH(AI8,$BN$6:$BN$53,0)),"") -> Corea del Sur | AM8: =INDEX($BE$6:$BN$53,MATCH($AL8,$BD$6:$BD$53,0),MATCH(AM$5,$BE$5:$BN$5,0)) -> 0 | AN8: =INDEX($BE$6:$BN$53,MATCH($AL8,$BD$6:$BD$53,0),MATCH(AN$5,$BE$5:$BN$5,0)) -> 0 | AO8: =INDEX($BE$6:$BN$53,MATCH($AL8,$BD$6:$BD$53,0),MATCH(AO$5,$BE$5:$BN$5,0)) -> 0 | AP8: =INDEX($BE$6:$BN$53,MATCH($AL8,$BD$6:$BD$53,0),MATCH(AP$5,$BE$5:$BN$5,0)) -> 0 | AQ8: =INDEX($BE$6:$BN$53,MATCH($AL8,$BD$6:$BD$53,0),MATCH(AQ$5,$BE$5:$BN$5,0)) -> 0 | AR8: =INDEX($BE$6:$BN$53,MATCH($AL8,$BD$6:$BD$53,0),MATCH(AR$5,$BE$5:$BN$5,0)) -> 0 | AS8: =INDEX($BE$6:$BN$53,MATCH($AL8,$BD$6:$BD$53,0),MATCH(AS$5,$BE$5:$BN$5,0)) -> 0 | AT8: =INDEX($BE$6:$BN$53,MATCH($AL8,$BD$6:$BD$53,0),MATCH(AT$5,$BE$5:$BN$5,0)) -> 0 | AU8: =INDEX($DL$6:$DL$53,MATCH(AI8,$DP$6:$DP$53,0)) -> 1 | AV8: =INDEX($BD$6:$BD$53,MATCH(AI8,$BM$6:$BM$53,0)) -> Corea del Sur | AY8: =+A7 -> Corea del Sur | BC8: =+INDEX(T_Equipos[Grupo],MATCH(WORLDCUP!BD8,T_Equipos[NombreEquipo],0)) -> A | BD8: =+Equipos!B4 -> Corea del Sur | BE8: =+BG8*3+BH8+IF($AZ$3="no",0,INDEX($AZ$6:$AZ$97,MATCH(BD8,$AY$6:$AY$97,0))) -> 0 | BF8: =+BG8+BH8+BI8 -> 0 | BG8: =+COUNTIFS(FGLocal,BD8,Ganador,"Local")+COUNTIFS(FGVisitante,BD8,Ganador,"Visitante") -> 0 | BH8: =+COUNTIFS(FGLocal,BD8,Ganador,"Empate")+COUNTIFS(FGVisitante,BD8,Ganador,"Empate") -> 0 | BI8: =+COUNTIFS(FGVisitante,BD8,Ganador,"Local")+COUNTIFS(FGLocal,BD8,Ganador,"Visitante") -> 0 | BJ8: =+SUMIFS(FG_GolesLocal,FGLocal,BD8,Ganador,"<>"&"Pendiente",FG_GolesLocal,"<>"&"",FG_GolesVisitante,"<>"&"")+SUMIFS(FG_GolesVisitante,FGVisitante,BD8,Ganador,"<>"&"Pendiente",FG_GolesLocal,"<>"&"",FG_GolesVisitante,"<>"&"") -> 0 | BK8: =+SUMIFS(FG_GolesLocal,FGVisitante,BD8,Ganador,"<>"&"Pendiente",FG_GolesLocal,"<>"&"",FG_GolesVisitante,"<>"&"")+SUMIFS(FG_GolesVisitante,FGLocal,BD8,Ganador,"<>"&"Pendiente",FG_GolesLocal,"<>"&"",FG_GolesVisitante,"<>"&"") -> 0 | BL8: =+BJ8-BK8 -> 0 | BM8: =DD8&BC8 -> 3A | BN8: =DH8&BC8 -> 3A | BO8: =IF(AND($AJ$99=144,BF8>=1),1,0) -> 0 | BP8: =COUNTIFS($BO$6:$BO$53,">"&BO8,$BC$6:$BC$53,INDEX(T_Equipos[Grupo],MATCH(BD8,T_Equipos[NombreEquipo],0)))+1 -> 1 | BQ8: =IF(COUNTIFS($BP$6:$BP$53,BP8,$BC$6:$BC$53,INDEX(T_Equipos[Grupo],MATCH(BD8,T_Equipos[NombreEquipo],0)))=1,"-","P."&BP8&" ("&COUNTIFS($BP$6:$BP$53,BP8,$BC$6:$BC$53,INDEX(T_Equipos[Grupo],MATCH(BD8,T_Equipos[NombreEquipo],0)))&")") -> P.1 (4) | BR8: =IF($BQ8="-","-",BE8) -> 0 | BS8: =BP8+COUNTIFS($BQ$6:$BQ$53,BQ8,$BR$6:BR$53,">"&BR8,$BC$6:$BC$53,INDEX(T_Equipos[Grupo],MATCH(BD8,T_Equipos[NombreEquipo],0))) -> 1 | BT8: =IF(COUNTIFS($BS$6:$BS$53,BS8,$BC$6:$BC$53,INDEX(T_Equipos[Grupo],MATCH(BD8,T_Equipos[NombreEquipo],0)))=1,"-","P."&BS8&" ("&COUNTIFS($BS$6:$BS$53,BS8,$BC$6:$BC$53,INDEX(T_Equipos[Grupo],MATCH(BD8,T_Equipos[NombreEquipo],0)))&")") -> P.1 (4) | BU8: =IF($BT8="-","-",COUNTIFS(FGLocal,$BD8,Ganador,"Local",Part1Empate1V,$BT8)+COUNTIFS(FGVisitante,$BD8,Ganador,"Visitante",Part1Empate1L,$BT8)) -> 0 | BV8: =IF($BT8="-","-",COUNTIFS(FGLocal,$BD8,Ganador,"Empate",Part1Empate1V,$BT8)+COUNTIFS(FGVisitante,$BD8,Ganador,"Empate",Part1Empate1L,$BT8)) -> 0 | BW8: =IF($BT8="-","-",COUNTIFS(FGLocal,$BD8,Ganador,"Visitante",Part1Empate1V,$BT8)+COUNTIFS(FGVisitante,$BD8,Ganador,"Local",Part1Empate1L,$BT8)) -> 0 | BX8: =IF($BT8="-","-",BU8*3+BV8) -> 0 | BY8: =BS8+COUNTIFS($BT$6:$BT$53,BT8,$BX$6:BX$53,">"&BX8,$BC$6:$BC$53,INDEX(T_Equipos[Grupo],MATCH(BD8,T_Equipos[NombreEquipo],0))) -> 1 | BZ8: =IF(COUNTIFS($BY$6:$BY$53,BY8,$BC$6:$BC$53,INDEX(T_Equipos[Grupo],MATCH(BD8,T_Equipos[NombreEquipo],0)))=1,"-","P."&BY8&" ("&COUNTIFS($BY$6:$BY$53,BY8,$BC$6:$BC$53,INDEX(T_Equipos[Grupo],MATCH(BD8,T_Equipos[NombreEquipo],0)))&")") -> P.1 (4) | CA8: =IF($BZ8="-","-",SUMIFS(FG_GolesLocal,FGLocal,$BD8,Part1Empate2V,$BZ8)+SUMIFS(FG_GolesVisitante,FGVisitante,$BD8,Part1Empate2L,$BZ8)) -> 0 | CB8: =IF($BZ8="-","-",SUMIFS(FG_GolesVisitante,FGLocal,$BD8,Part1Empate2V,$BZ8)+SUMIFS(FG_GolesLocal,FGVisitante,$BD8,Part1Empate2L,$BZ8)) -> 0 | CC8: =IF($BZ8="-","-",CA8-CB8) -> 0 | CD8: =BY8+COUNTIFS($BZ$6:$BZ$53,BZ8,$CC$6:CC$53,">"&CC8,$BC$6:$BC$53,INDEX(T_Equipos[Grupo],MATCH(BD8,T_Equipos[NombreEquipo],0))) -> 1 | CE8: =IF(COUNTIFS($CD$6:$CD$53,CD8,$BC$6:$BC$53,INDEX(T_Equipos[Grupo],MATCH(BD8,T_Equipos[NombreEquipo],0)))=1,"-","P."&CD8&" ("&COUNTIFS($CD$6:$CD$53,CD8,$BC$6:$BC$53,INDEX(T_Equipos[Grupo],MATCH(BD8,T_Equipos[NombreEquipo],0)))&")") -> P.1 (4) | CF8: =IF($CE8="-","-",SUMIFS(FG_GolesLocal,FGLocal,$BD8,Part1Empate3V,$CE8)+SUMIFS(FG_GolesVisitante,FGVisitante,$BD8,Part1Empate3L,$CE8)) -> 0 | CG8: =CD8+COUNTIFS($CE$6:$CE$53,CE8,$CF$6:CF$53,">"&CF8,$BC$6:$BC$53,INDEX(T_Equipos[Grupo],MATCH(BD8,T_Equipos[NombreEquipo],0))) -> 1 | CH8: =IF(COUNTIFS($CG$6:$CG$53,CG8,$BC$6:$BC$53,INDEX(T_Equipos[Grupo],MATCH(BD8,T_Equipos[NombreEquipo],0)))=1,"-","P."&CG8&" ("&COUNTIFS($CG$6:$CG$53,CG8,$BC$6:$BC$53,INDEX(T_Equipos[Grupo],MATCH(BD8,T_Equipos[NombreEquipo],0)))&")") -> P.1 (4) | CI8: =IF($CH8="-","-",COUNTIFS(FGLocal,$BD8,Ganador,"Local",Part2Empate4V,$CH8)+COUNTIFS(FGVisitante,$BD8,Ganador,"Visitante",Part2Empate4L,$CH8)) -> 0 | CJ8: =IF($CH8="-","-",COUNTIFS(FGLocal,$BD8,Ganador,"Empate",Part2Empate4V,$CH8)+COUNTIFS(FGVisitante,$BD8,Ganador,"Empate",Part2Empate4L,$CH8)) -> 0 | CK8: =IF($CH8="-","-",COUNTIFS(FGLocal,$BD8,Ganador,"Visitante",Part2Empate4V,$CH8)+COUNTIFS(FGVisitante,$BD8,Ganador,"Local",Part2Empate4L,$CH8)) -> 0 | CL8: =IF($CH8="-","-",CI8*3+CJ8) -> 0 | CM8: =CG8+COUNTIFS($CH$6:$CH$53,CH8,$CL$6:CL$53,">"&CL8,$BC$6:$BC$53,INDEX(T_Equipos[Grupo],MATCH(BD8,T_Equipos[NombreEquipo],0))) -> 1 | CN8: =IF(COUNTIFS($CM$6:$CM$53,CM8,$BC$6:$BC$53,INDEX(T_Equipos[Grupo],MATCH(BD8,T_Equipos[NombreEquipo],0)))=1,"-","P."&CM8&" ("&COUNTIFS($CM$6:$CM$53,CM8,$BC$6:$BC$53,INDEX(T_Equipos[Grupo],MATCH(BD8,T_Equipos[NombreEquipo],0)))&")") -> P.1 (4) | CO8: =IF($CN8="-","-",SUMIFS(FG_GolesLocal,FGLocal,$BD8,Part2Empate5V,$CN8)+SUMIFS(FG_GolesVisitante,FGVisitante,$BD8,Part2Empate5L,$CN8)) -> 0 | CP8: =IF($CN8="-","-",SUMIFS(FG_GolesVisitante,FGLocal,$BD8,Part2Empate5V,$CN8)+SUMIFS(FG_GolesLocal,FGVisitante,$BD8,Part2Empate5L,$CN8)) -> 0 | CQ8: =IF($CN8="-","-",CO8-CP8) -> 0 | CR8: =CM8+COUNTIFS($CN$6:$CN$53,CN8,$CQ$6:CQ$53,">"&CQ8,$BC$6:$BC$53,INDEX(T_Equipos[Grupo],MATCH(BD8,T_Equipos[NombreEquipo],0))) -> 1 | CS8: =IF(COUNTIFS($CR$6:$CR$53,CR8,$BC$6:$BC$53,INDEX(T_Equipos[Grupo],MATCH(BD8,T_Equipos[NombreEquipo],0)))=1,"-","P."&CR8&" ("&COUNTIFS($CR$6:$CR$53,CR8,$BC$6:$BC$53,INDEX(T_Equipos[Grupo],MATCH(BD8,T_Equipos[NombreEquipo],0)))&")") -> P.1 (4) | CT8: =IF($CS8="-","-",SUMIFS(FG_GolesLocal,FGLocal,$BD8,Part2Empate6V,$CS8)+SUMIFS(FG_GolesVisitante,FGVisitante,$BD8,Part2Empate6L,$CS8)) -> 0 | CU8: =CR8+COUNTIFS($CS$6:$CS$53,CS8,$CT$6:CT$53,">"&CT8,$BC$6:$BC$53,INDEX(T_Equipos[Grupo],MATCH(BD8,T_Equipos[NombreEquipo],0))) -> 1 | CV8: =IF(COUNTIFS($CU$6:$CU$53,CU8,$BC$6:$BC$53,INDEX(T_Equipos[Grupo],MATCH(BD8,T_Equipos[NombreEquipo],0)))=1,"-","P."&CU8&" ("&COUNTIFS($CU$6:$CU$53,CU8,$BC$6:$BC$53,INDEX(T_Equipos[Grupo],MATCH(BD8,T_Equipos[NombreEquipo],0)))&")") -> P.1 (4) | CW8: =IF(CV8="-","-",BL8) -> 0 | CX8: =CU8+COUNTIFS($CV$6:$CV$53,CV8,$CW$6:CW$53,">"&CW8,$BC$6:$BC$53,INDEX(T_Equipos[Grupo],MATCH(BD8,T_Equipos[NombreEquipo],0))) -> 1 | CY8: =IF(COUNTIFS($CX$6:$CX$53,CX8,$BC$6:$BC$53,INDEX(T_Equipos[Grupo],MATCH(BD8,T_Equipos[NombreEquipo],0)))=1,"-","P."&CX8&" ("&COUNTIFS($CX$6:$CX$53,CX8,$BC$6:$BC$53,INDEX(T_Equipos[Grupo],MATCH(BD8,T_Equipos[NombreEquipo],0)))&")") -> P.1 (4) | CZ8: =IF(CY8="-","-",BJ8) -> 0 | DA8: =CX8+COUNTIFS($CY$6:$CY$53,CY8,$CZ$6:CZ$53,">"&CZ8,$BC$6:$BC$53,INDEX(T_Equipos[Grupo],MATCH(BD8,T_Equipos[NombreEquipo],0))) -> 1 | DB8: =IF(COUNTIFS($DA$6:$DA$53,DA8,$BC$6:$BC$53,INDEX(T_Equipos[Grupo],MATCH(BD8,T_Equipos[NombreEquipo],0)))=1,"-","P."&DA8&" ("&COUNTIFS($DA$6:$DA$53,DA8,$BC$6:$BC$53,INDEX(T_Equipos[Grupo],MATCH(BD8,T_Equipos[NombreEquipo],0)))&")") -> P.1 (4) | DC8: =IF(DB8="-","-",COUNTIFS(T_Equipos[Rank],"<"&INDEX(T_Equipos[Rank],MATCH(BD8,T_Equipos[NombreEquipo],0)),$BC$6:$BC$53,INDEX(T_Equipos[Grupo],MATCH(BD8,T_Equipos[NombreEquipo],0)))+1) -> 3 | DD8: =DA8+COUNTIFS($DB$6:$DB$53,DB8,$DC$6:DC$53,"<"&DC8,$BC$6:$BC$53,INDEX(T_Equipos[Grupo],MATCH(BD8,T_Equipos[NombreEquipo],0))) -> 3 | DF8: =IF(OR(INDEX($AW$6:$AW$97,MATCH($BD8,$AV$6:$AV$97,0))="",DB8="-"),DD8,INDEX($AW$6:$AW$97,MATCH($BD8,$AV$6:$AV$97,0))+DD8/1000) -> 3 | DG8: =IF(DB8="-","-",COUNTIFS(DF$6:DF$53,"<"&DF8,$BC$6:$BC$53,INDEX(T_Equipos[Grupo],MATCH(BD8,T_Equipos[NombreEquipo],0)))) -> 2 | DH8: =DA8+COUNTIFS(DB$6:DB$53,DB8,DG$6:DG$53,"<"&DG8,$BC$6:$BC$53,INDEX(T_Equipos[Grupo],MATCH(BD8,T_Equipos[NombreEquipo],0))) -> 3 | DJ8: =INDEX($DA$6:$DA$53,MATCH($DQ8,$BD$6:$BD$53,0)) -> 1 | DK8: =+SUMIF($BC$6:$BC$53,BC8,$BF$6:$BF$53) -> 0 | DL8: =IF(OR(DK8=12,$AJ$99=144),COUNTIFS($DJ$6:$DJ$53,DJ8,$BC$6:$BC$53,BC8),1) -> 1 | DM8: =DJ8&"."&DL8 -> 1.1 | DN8: {=OFFSET(Horarios!$P$3,DJ8-1,0,DL8,1)} -> 1 | DP8: 3A | DQ8: =INDEX($BD$6:$BD$53,MATCH(DP8,$BM$6:$BM$53,0)) -> Corea del Sur | DT8: =AA8&"-"&AF8 -> República Checa-México
D9: =IF(OR(AC9="",AD9=""),"Pendiente",IF(AC9>AD9,"Local",IF(AC9<AD9,"Visitante","Empate"))) -> Pendiente | E9: =IF(D9="Pendiente","-",INDEX($BT$6:$BT$53,MATCH($AA9,$BD$6:$BD$53,0))) -> - | F9: =IF(D9="Pendiente","-",INDEX($BT$6:$BT$53,MATCH($AF9,$BD$6:$BD$53,0))) -> - | H9: =IF(D9="Pendiente","-",INDEX($BZ$6:$BZ$53,MATCH($AA9,$BD$6:$BD$53,0))) -> - | I9: =IF(D9="Pendiente","-",INDEX($BZ$6:$BZ$53,MATCH($AF9,$BD$6:$BD$53,0))) -> - | K9: =IF(D9="Pendiente","-",INDEX($CE$6:$CE$53,MATCH($AA9,$BD$6:$BD$53,0))) -> - | L9: =IF(D9="Pendiente","-",INDEX($CE$6:$CE$53,MATCH($AF9,$BD$6:$BD$53,0))) -> - | N9: =IF(D9="Pendiente","-",INDEX($CH$6:$CH$53,MATCH($AA9,$BD$6:$BD$53,0))) -> - | O9: =IF(D9="Pendiente","-",INDEX($CH$6:$CH$53,MATCH($AF9,$BD$6:$BD$53,0))) -> - | Q9: =IF(D9="Pendiente","-",INDEX($CN$6:$CN$53,MATCH($AA9,$BD$6:$BD$53,0))) -> - | R9: =IF(D9="Pendiente","-",INDEX($CN$6:$CN$53,MATCH($AF9,$BD$6:$BD$53,0))) -> - | T9: =IF(D9="Pendiente","-",INDEX($CS$6:$CS$53,MATCH($AA9,$BD$6:$BD$53,0))) -> - | U9: =IF(D9="Pendiente","-",INDEX($CS$6:$CS$53,MATCH($AF9,$BD$6:$BD$53,0))) -> - | X9: =Horarios!C9 -> 46197.875 | Y9: =Horarios!C9 -> 46197.875 | Z9: =$Z$8 -> J3 | AA9: =A6 -> Sudáfrica | AB9: {=Ver_flag_local} | AE9: {=Ver_flag_visit} | AF9: =A7 -> Corea del Sur | AG9: =IF(NOT(OR(ISBLANK(AC9),ISBLANK(AD9))),1,0) -> 0 | AH9: 54 | AI9: =AJ9&$B$4 -> 4A | AJ9: 4 | AK9: {=Ver_flag_visit} | AL9: =IFERROR(INDEX($BD$6:$BD$53,MATCH(AI9,$BN$6:$BN$53,0)),"") -> República Checa | AM9: =INDEX($BE$6:$BN$53,MATCH($AL9,$BD$6:$BD$53,0),MATCH(AM$5,$BE$5:$BN$5,0)) -> 0 | AN9: =INDEX($BE$6:$BN$53,MATCH($AL9,$BD$6:$BD$53,0),MATCH(AN$5,$BE$5:$BN$5,0)) -> 0 | AO9: =INDEX($BE$6:$BN$53,MATCH($AL9,$BD$6:$BD$53,0),MATCH(AO$5,$BE$5:$BN$5,0)) -> 0 | AP9: =INDEX($BE$6:$BN$53,MATCH($AL9,$BD$6:$BD$53,0),MATCH(AP$5,$BE$5:$BN$5,0)) -> 0 | AQ9: =INDEX($BE$6:$BN$53,MATCH($AL9,$BD$6:$BD$53,0),MATCH(AQ$5,$BE$5:$BN$5,0)) -> 0 | AR9: =INDEX($BE$6:$BN$53,MATCH($AL9,$BD$6:$BD$53,0),MATCH(AR$5,$BE$5:$BN$5,0)) -> 0 | AS9: =INDEX($BE$6:$BN$53,MATCH($AL9,$BD$6:$BD$53,0),MATCH(AS$5,$BE$5:$BN$5,0)) -> 0 | AT9: =INDEX($BE$6:$BN$53,MATCH($AL9,$BD$6:$BD$53,0),MATCH(AT$5,$BE$5:$BN$5,0)) -> 0 | AU9: =INDEX($DL$6:$DL$53,MATCH(AI9,$DP$6:$DP$53,0)) -> 1 | AV9: =INDEX($BD$6:$BD$53,MATCH(AI9,$BM$6:$BM$53,0)) -> República Checa | AY9: =+A8 -> República Checa | BC9: =+INDEX(T_Equipos[Grupo],MATCH(WORLDCUP!BD9,T_Equipos[NombreEquipo],0)) -> A | BD9: =+Equipos!B5 -> República Checa | BE9: =+BG9*3+BH9+IF($AZ$3="no",0,INDEX($AZ$6:$AZ$97,MATCH(BD9,$AY$6:$AY$97,0))) -> 0 | BF9: =+BG9+BH9+BI9 -> 0 | BG9: =+COUNTIFS(FGLocal,BD9,Ganador,"Local")+COUNTIFS(FGVisitante,BD9,Ganador,"Visitante") -> 0 | BH9: =+COUNTIFS(FGLocal,BD9,Ganador,"Empate")+COUNTIFS(FGVisitante,BD9,Ganador,"Empate") -> 0 | BI9: =+COUNTIFS(FGVisitante,BD9,Ganador,"Local")+COUNTIFS(FGLocal,BD9,Ganador,"Visitante") -> 0 | BJ9: =+SUMIFS(FG_GolesLocal,FGLocal,BD9,Ganador,"<>"&"Pendiente",FG_GolesLocal,"<>"&"",FG_GolesVisitante,"<>"&"")+SUMIFS(FG_GolesVisitante,FGVisitante,BD9,Ganador,"<>"&"Pendiente",FG_GolesLocal,"<>"&"",FG_GolesVisitante,"<>"&"") -> 0 | BK9: =+SUMIFS(FG_GolesLocal,FGVisitante,BD9,Ganador,"<>"&"Pendiente",FG_GolesLocal,"<>"&"",FG_GolesVisitante,"<>"&"")+SUMIFS(FG_GolesVisitante,FGLocal,BD9,Ganador,"<>"&"Pendiente",FG_GolesLocal,"<>"&"",FG_GolesVisitante,"<>"&"") -> 0 | BL9: =+BJ9-BK9 -> 0 | BM9: =DD9&BC9 -> 4A | BN9: =DH9&BC9 -> 4A | BO9: =IF(AND($AJ$99=144,BF9>=1),1,0) -> 0 | BP9: =COUNTIFS($BO$6:$BO$53,">"&BO9,$BC$6:$BC$53,INDEX(T_Equipos[Grupo],MATCH(BD9,T_Equipos[NombreEquipo],0)))+1 -> 1 | BQ9: =IF(COUNTIFS($BP$6:$BP$53,BP9,$BC$6:$BC$53,INDEX(T_Equipos[Grupo],MATCH(BD9,T_Equipos[NombreEquipo],0)))=1,"-","P."&BP9&" ("&COUNTIFS($BP$6:$BP$53,BP9,$BC$6:$BC$53,INDEX(T_Equipos[Grupo],MATCH(BD9,T_Equipos[NombreEquipo],0)))&")") -> P.1 (4) | BR9: =IF($BQ9="-","-",BE9) -> 0 | BS9: =BP9+COUNTIFS($BQ$6:$BQ$53,BQ9,$BR$6:BR$53,">"&BR9,$BC$6:$BC$53,INDEX(T_Equipos[Grupo],MATCH(BD9,T_Equipos[NombreEquipo],0))) -> 1 | BT9: =IF(COUNTIFS($BS$6:$BS$53,BS9,$BC$6:$BC$53,INDEX(T_Equipos[Grupo],MATCH(BD9,T_Equipos[NombreEquipo],0)))=1,"-","P."&BS9&" ("&COUNTIFS($BS$6:$BS$53,BS9,$BC$6:$BC$53,INDEX(T_Equipos[Grupo],MATCH(BD9,T_Equipos[NombreEquipo],0)))&")") -> P.1 (4) | BU9: =IF($BT9="-","-",COUNTIFS(FGLocal,$BD9,Ganador,"Local",Part1Empate1V,$BT9)+COUNTIFS(FGVisitante,$BD9,Ganador,"Visitante",Part1Empate1L,$BT9)) -> 0 | BV9: =IF($BT9="-","-",COUNTIFS(FGLocal,$BD9,Ganador,"Empate",Part1Empate1V,$BT9)+COUNTIFS(FGVisitante,$BD9,Ganador,"Empate",Part1Empate1L,$BT9)) -> 0 | BW9: =IF($BT9="-","-",COUNTIFS(FGLocal,$BD9,Ganador,"Visitante",Part1Empate1V,$BT9)+COUNTIFS(FGVisitante,$BD9,Ganador,"Local",Part1Empate1L,$BT9)) -> 0 | BX9: =IF($BT9="-","-",BU9*3+BV9) -> 0 | BY9: =BS9+COUNTIFS($BT$6:$BT$53,BT9,$BX$6:BX$53,">"&BX9,$BC$6:$BC$53,INDEX(T_Equipos[Grupo],MATCH(BD9,T_Equipos[NombreEquipo],0))) -> 1 | BZ9: =IF(COUNTIFS($BY$6:$BY$53,BY9,$BC$6:$BC$53,INDEX(T_Equipos[Grupo],MATCH(BD9,T_Equipos[NombreEquipo],0)))=1,"-","P."&BY9&" ("&COUNTIFS($BY$6:$BY$53,BY9,$BC$6:$BC$53,INDEX(T_Equipos[Grupo],MATCH(BD9,T_Equipos[NombreEquipo],0)))&")") -> P.1 (4) | CA9: =IF($BZ9="-","-",SUMIFS(FG_GolesLocal,FGLocal,$BD9,Part1Empate2V,$BZ9)+SUMIFS(FG_GolesVisitante,FGVisitante,$BD9,Part1Empate2L,$BZ9)) -> 0 | CB9: =IF($BZ9="-","-",SUMIFS(FG_GolesVisitante,FGLocal,$BD9,Part1Empate2V,$BZ9)+SUMIFS(FG_GolesLocal,FGVisitante,$BD9,Part1Empate2L,$BZ9)) -> 0 | CC9: =IF($BZ9="-","-",CA9-CB9) -> 0 | CD9: =BY9+COUNTIFS($BZ$6:$BZ$53,BZ9,$CC$6:CC$53,">"&CC9,$BC$6:$BC$53,INDEX(T_Equipos[Grupo],MATCH(BD9,T_Equipos[NombreEquipo],0))) -> 1 | CE9: =IF(COUNTIFS($CD$6:$CD$53,CD9,$BC$6:$BC$53,INDEX(T_Equipos[Grupo],MATCH(BD9,T_Equipos[NombreEquipo],0)))=1,"-","P."&CD9&" ("&COUNTIFS($CD$6:$CD$53,CD9,$BC$6:$BC$53,INDEX(T_Equipos[Grupo],MATCH(BD9,T_Equipos[NombreEquipo],0)))&")") -> P.1 (4) | CF9: =IF($CE9="-","-",SUMIFS(FG_GolesLocal,FGLocal,$BD9,Part1Empate3V,$CE9)+SUMIFS(FG_GolesVisitante,FGVisitante,$BD9,Part1Empate3L,$CE9)) -> 0 | CG9: =CD9+COUNTIFS($CE$6:$CE$53,CE9,$CF$6:CF$53,">"&CF9,$BC$6:$BC$53,INDEX(T_Equipos[Grupo],MATCH(BD9,T_Equipos[NombreEquipo],0))) -> 1 | CH9: =IF(COUNTIFS($CG$6:$CG$53,CG9,$BC$6:$BC$53,INDEX(T_Equipos[Grupo],MATCH(BD9,T_Equipos[NombreEquipo],0)))=1,"-","P."&CG9&" ("&COUNTIFS($CG$6:$CG$53,CG9,$BC$6:$BC$53,INDEX(T_Equipos[Grupo],MATCH(BD9,T_Equipos[NombreEquipo],0)))&")") -> P.1 (4) | CI9: =IF($CH9="-","-",COUNTIFS(FGLocal,$BD9,Ganador,"Local",Part2Empate4V,$CH9)+COUNTIFS(FGVisitante,$BD9,Ganador,"Visitante",Part2Empate4L,$CH9)) -> 0 | CJ9: =IF($CH9="-","-",COUNTIFS(FGLocal,$BD9,Ganador,"Empate",Part2Empate4V,$CH9)+COUNTIFS(FGVisitante,$BD9,Ganador,"Empate",Part2Empate4L,$CH9)) -> 0 | CK9: =IF($CH9="-","-",COUNTIFS(FGLocal,$BD9,Ganador,"Visitante",Part2Empate4V,$CH9)+COUNTIFS(FGVisitante,$BD9,Ganador,"Local",Part2Empate4L,$CH9)) -> 0 | CL9: =IF($CH9="-","-",CI9*3+CJ9) -> 0 | CM9: =CG9+COUNTIFS($CH$6:$CH$53,CH9,$CL$6:CL$53,">"&CL9,$BC$6:$BC$53,INDEX(T_Equipos[Grupo],MATCH(BD9,T_Equipos[NombreEquipo],0))) -> 1 | CN9: =IF(COUNTIFS($CM$6:$CM$53,CM9,$BC$6:$BC$53,INDEX(T_Equipos[Grupo],MATCH(BD9,T_Equipos[NombreEquipo],0)))=1,"-","P."&CM9&" ("&COUNTIFS($CM$6:$CM$53,CM9,$BC$6:$BC$53,INDEX(T_Equipos[Grupo],MATCH(BD9,T_Equipos[NombreEquipo],0)))&")") -> P.1 (4) | CO9: =IF($CN9="-","-",SUMIFS(FG_GolesLocal,FGLocal,$BD9,Part2Empate5V,$CN9)+SUMIFS(FG_GolesVisitante,FGVisitante,$BD9,Part2Empate5L,$CN9)) -> 0 | CP9: =IF($CN9="-","-",SUMIFS(FG_GolesVisitante,FGLocal,$BD9,Part2Empate5V,$CN9)+SUMIFS(FG_GolesLocal,FGVisitante,$BD9,Part2Empate5L,$CN9)) -> 0 | CQ9: =IF($CN9="-","-",CO9-CP9) -> 0 | CR9: =CM9+COUNTIFS($CN$6:$CN$53,CN9,$CQ$6:CQ$53,">"&CQ9,$BC$6:$BC$53,INDEX(T_Equipos[Grupo],MATCH(BD9,T_Equipos[NombreEquipo],0))) -> 1 | CS9: =IF(COUNTIFS($CR$6:$CR$53,CR9,$BC$6:$BC$53,INDEX(T_Equipos[Grupo],MATCH(BD9,T_Equipos[NombreEquipo],0)))=1,"-","P."&CR9&" ("&COUNTIFS($CR$6:$CR$53,CR9,$BC$6:$BC$53,INDEX(T_Equipos[Grupo],MATCH(BD9,T_Equipos[NombreEquipo],0)))&")") -> P.1 (4) | CT9: =IF($CS9="-","-",SUMIFS(FG_GolesLocal,FGLocal,$BD9,Part2Empate6V,$CS9)+SUMIFS(FG_GolesVisitante,FGVisitante,$BD9,Part2Empate6L,$CS9)) -> 0 | CU9: =CR9+COUNTIFS($CS$6:$CS$53,CS9,$CT$6:CT$53,">"&CT9,$BC$6:$BC$53,INDEX(T_Equipos[Grupo],MATCH(BD9,T_Equipos[NombreEquipo],0))) -> 1 | CV9: =IF(COUNTIFS($CU$6:$CU$53,CU9,$BC$6:$BC$53,INDEX(T_Equipos[Grupo],MATCH(BD9,T_Equipos[NombreEquipo],0)))=1,"-","P."&CU9&" ("&COUNTIFS($CU$6:$CU$53,CU9,$BC$6:$BC$53,INDEX(T_Equipos[Grupo],MATCH(BD9,T_Equipos[NombreEquipo],0)))&")") -> P.1 (4) | CW9: =IF(CV9="-","-",BL9) -> 0 | CX9: =CU9+COUNTIFS($CV$6:$CV$53,CV9,$CW$6:CW$53,">"&CW9,$BC$6:$BC$53,INDEX(T_Equipos[Grupo],MATCH(BD9,T_Equipos[NombreEquipo],0))) -> 1 | CY9: =IF(COUNTIFS($CX$6:$CX$53,CX9,$BC$6:$BC$53,INDEX(T_Equipos[Grupo],MATCH(BD9,T_Equipos[NombreEquipo],0)))=1,"-","P."&CX9&" ("&COUNTIFS($CX$6:$CX$53,CX9,$BC$6:$BC$53,INDEX(T_Equipos[Grupo],MATCH(BD9,T_Equipos[NombreEquipo],0)))&")") -> P.1 (4) | CZ9: =IF(CY9="-","-",BJ9) -> 0 | DA9: =CX9+COUNTIFS($CY$6:$CY$53,CY9,$CZ$6:CZ$53,">"&CZ9,$BC$6:$BC$53,INDEX(T_Equipos[Grupo],MATCH(BD9,T_Equipos[NombreEquipo],0))) -> 1 | DB9: =IF(COUNTIFS($DA$6:$DA$53,DA9,$BC$6:$BC$53,INDEX(T_Equipos[Grupo],MATCH(BD9,T_Equipos[NombreEquipo],0)))=1,"-","P."&DA9&" ("&COUNTIFS($DA$6:$DA$53,DA9,$BC$6:$BC$53,INDEX(T_Equipos[Grupo],MATCH(BD9,T_Equipos[NombreEquipo],0)))&")") -> P.1 (4) | DC9: =IF(DB9="-","-",COUNTIFS(T_Equipos[Rank],"<"&INDEX(T_Equipos[Rank],MATCH(BD9,T_Equipos[NombreEquipo],0)),$BC$6:$BC$53,INDEX(T_Equipos[Grupo],MATCH(BD9,T_Equipos[NombreEquipo],0)))+1) -> 4 | DD9: =DA9+COUNTIFS($DB$6:$DB$53,DB9,$DC$6:DC$53,"<"&DC9,$BC$6:$BC$53,INDEX(T_Equipos[Grupo],MATCH(BD9,T_Equipos[NombreEquipo],0))) -> 4 | DF9: =IF(OR(INDEX($AW$6:$AW$97,MATCH($BD9,$AV$6:$AV$97,0))="",DB9="-"),DD9,INDEX($AW$6:$AW$97,MATCH($BD9,$AV$6:$AV$97,0))+DD9/1000) -> 4 | DG9: =IF(DB9="-","-",COUNTIFS(DF$6:DF$53,"<"&DF9,$BC$6:$BC$53,INDEX(T_Equipos[Grupo],MATCH(BD9,T_Equipos[NombreEquipo],0)))) -> 3 | DH9: =DA9+COUNTIFS(DB$6:DB$53,DB9,DG$6:DG$53,"<"&DG9,$BC$6:$BC$53,INDEX(T_Equipos[Grupo],MATCH(BD9,T_Equipos[NombreEquipo],0))) -> 4 | DJ9: =INDEX($DA$6:$DA$53,MATCH($DQ9,$BD$6:$BD$53,0)) -> 1 | DK9: =+SUMIF($BC$6:$BC$53,BC9,$BF$6:$BF$53) -> 0 | DL9: =IF(OR(DK9=12,$AJ$99=144),COUNTIFS($DJ$6:$DJ$53,DJ9,$BC$6:$BC$53,BC9),1) -> 1 | DM9: =DJ9&"."&DL9 -> 1.1 | DN9: {=OFFSET(Horarios!$P$3,DJ9-1,0,DL9,1)} -> 1 | DP9: 4A | DQ9: =INDEX($BD$6:$BD$53,MATCH(DP9,$BM$6:$BM$53,0)) -> República Checa | DT9: =AA9&"-"&AF9 -> Sudáfrica-Corea del Sur
BC10: =+INDEX(T_Equipos[Grupo],MATCH(WORLDCUP!BD10,T_Equipos[NombreEquipo],0)) -> B | BD10: =+Equipos!B6 -> Canadá | BE10: =+BG10*3+BH10+IF($AZ$3="no",0,INDEX($AZ$6:$AZ$97,MATCH(BD10,$AY$6:$AY$97,0))) -> 0 | BF10: =+BG10+BH10+BI10 -> 0 | BG10: =+COUNTIFS(FGLocal,BD10,Ganador,"Local")+COUNTIFS(FGVisitante,BD10,Ganador,"Visitante") -> 0 | BH10: =+COUNTIFS(FGLocal,BD10,Ganador,"Empate")+COUNTIFS(FGVisitante,BD10,Ganador,"Empate") -> 0 | BI10: =+COUNTIFS(FGVisitante,BD10,Ganador,"Local")+COUNTIFS(FGLocal,BD10,Ganador,"Visitante") -> 0 | BJ10: =+SUMIFS(FG_GolesLocal,FGLocal,BD10,Ganador,"<>"&"Pendiente",FG_GolesLocal,"<>"&"",FG_GolesVisitante,"<>"&"")+SUMIFS(FG_GolesVisitante,FGVisitante,BD10,Ganador,"<>"&"Pendiente",FG_GolesLocal,"<>"&"",FG_GolesVisitante,"<>"&"") -> 0 | BK10: =+SUMIFS(FG_GolesLocal,FGVisitante,BD10,Ganador,"<>"&"Pendiente",FG_GolesLocal,"<>"&"",FG_GolesVisitante,"<>"&"")+SUMIFS(FG_GolesVisitante,FGLocal,BD10,Ganador,"<>"&"Pendiente",FG_GolesLocal,"<>"&"",FG_GolesVisitante,"<>"&"") -> 0 | BL10: =+BJ10-BK10 -> 0 | BM10: =DD10&BC10 -> 1B | BN10: =DH10&BC10 -> 1B | BO10: =IF(AND($AJ$99=144,BF10>=1),1,0) -> 0 | BP10: =COUNTIFS($BO$6:$BO$53,">"&BO10,$BC$6:$BC$53,INDEX(T_Equipos[Grupo],MATCH(BD10,T_Equipos[NombreEquipo],0)))+1 -> 1 | BQ10: =IF(COUNTIFS($BP$6:$BP$53,BP10,$BC$6:$BC$53,INDEX(T_Equipos[Grupo],MATCH(BD10,T_Equipos[NombreEquipo],0)))=1,"-","P."&BP10&" ("&COUNTIFS($BP$6:$BP$53,BP10,$BC$6:$BC$53,INDEX(T_Equipos[Grupo],MATCH(BD10,T_Equipos[NombreEquipo],0)))&")") -> P.1 (4) | BR10: =IF($BQ10="-","-",BE10) -> 0 | BS10: =BP10+COUNTIFS($BQ$6:$BQ$53,BQ10,$BR$6:BR$53,">"&BR10,$BC$6:$BC$53,INDEX(T_Equipos[Grupo],MATCH(BD10,T_Equipos[NombreEquipo],0))) -> 1 | BT10: =IF(COUNTIFS($BS$6:$BS$53,BS10,$BC$6:$BC$53,INDEX(T_Equipos[Grupo],MATCH(BD10,T_Equipos[NombreEquipo],0)))=1,"-","P."&BS10&" ("&COUNTIFS($BS$6:$BS$53,BS10,$BC$6:$BC$53,INDEX(T_Equipos[Grupo],MATCH(BD10,T_Equipos[NombreEquipo],0)))&")") -> P.1 (4) | BU10: =IF($BT10="-","-",COUNTIFS(FGLocal,$BD10,Ganador,"Local",Part1Empate1V,$BT10)+COUNTIFS(FGVisitante,$BD10,Ganador,"Visitante",Part1Empate1L,$BT10)) -> 0 | BV10: =IF($BT10="-","-",COUNTIFS(FGLocal,$BD10,Ganador,"Empate",Part1Empate1V,$BT10)+COUNTIFS(FGVisitante,$BD10,Ganador,"Empate",Part1Empate1L,$BT10)) -> 0 | BW10: =IF($BT10="-","-",COUNTIFS(FGLocal,$BD10,Ganador,"Visitante",Part1Empate1V,$BT10)+COUNTIFS(FGVisitante,$BD10,Ganador,"Local",Part1Empate1L,$BT10)) -> 0 | BX10: =IF($BT10="-","-",BU10*3+BV10) -> 0 | BY10: =BS10+COUNTIFS($BT$6:$BT$53,BT10,$BX$6:BX$53,">"&BX10,$BC$6:$BC$53,INDEX(T_Equipos[Grupo],MATCH(BD10,T_Equipos[NombreEquipo],0))) -> 1 | BZ10: =IF(COUNTIFS($BY$6:$BY$53,BY10,$BC$6:$BC$53,INDEX(T_Equipos[Grupo],MATCH(BD10,T_Equipos[NombreEquipo],0)))=1,"-","P."&BY10&" ("&COUNTIFS($BY$6:$BY$53,BY10,$BC$6:$BC$53,INDEX(T_Equipos[Grupo],MATCH(BD10,T_Equipos[NombreEquipo],0)))&")") -> P.1 (4) | CA10: =IF($BZ10="-","-",SUMIFS(FG_GolesLocal,FGLocal,$BD10,Part1Empate2V,$BZ10)+SUMIFS(FG_GolesVisitante,FGVisitante,$BD10,Part1Empate2L,$BZ10)) -> 0 | CB10: =IF($BZ10="-","-",SUMIFS(FG_GolesVisitante,FGLocal,$BD10,Part1Empate2V,$BZ10)+SUMIFS(FG_GolesLocal,FGVisitante,$BD10,Part1Empate2L,$BZ10)) -> 0 | CC10: =IF($BZ10="-","-",CA10-CB10) -> 0 | CD10: =BY10+COUNTIFS($BZ$6:$BZ$53,BZ10,$CC$6:CC$53,">"&CC10,$BC$6:$BC$53,INDEX(T_Equipos[Grupo],MATCH(BD10,T_Equipos[NombreEquipo],0))) -> 1 | CE10: =IF(COUNTIFS($CD$6:$CD$53,CD10,$BC$6:$BC$53,INDEX(T_Equipos[Grupo],MATCH(BD10,T_Equipos[NombreEquipo],0)))=1,"-","P."&CD10&" ("&COUNTIFS($CD$6:$CD$53,CD10,$BC$6:$BC$53,INDEX(T_Equipos[Grupo],MATCH(BD10,T_Equipos[NombreEquipo],0)))&")") -> P.1 (4) | CF10: =IF($CE10="-","-",SUMIFS(FG_GolesLocal,FGLocal,$BD10,Part1Empate3V,$CE10)+SUMIFS(FG_GolesVisitante,FGVisitante,$BD10,Part1Empate3L,$CE10)) -> 0 | CG10: =CD10+COUNTIFS($CE$6:$CE$53,CE10,$CF$6:CF$53,">"&CF10,$BC$6:$BC$53,INDEX(T_Equipos[Grupo],MATCH(BD10,T_Equipos[NombreEquipo],0))) -> 1 | CH10: =IF(COUNTIFS($CG$6:$CG$53,CG10,$BC$6:$BC$53,INDEX(T_Equipos[Grupo],MATCH(BD10,T_Equipos[NombreEquipo],0)))=1,"-","P."&CG10&" ("&COUNTIFS($CG$6:$CG$53,CG10,$BC$6:$BC$53,INDEX(T_Equipos[Grupo],MATCH(BD10,T_Equipos[NombreEquipo],0)))&")") -> P.1 (4) | CI10: =IF($CH10="-","-",COUNTIFS(FGLocal,$BD10,Ganador,"Local",Part2Empate4V,$CH10)+COUNTIFS(FGVisitante,$BD10,Ganador,"Visitante",Part2Empate4L,$CH10)) -> 0 | CJ10: =IF($CH10="-","-",COUNTIFS(FGLocal,$BD10,Ganador,"Empate",Part2Empate4V,$CH10)+COUNTIFS(FGVisitante,$BD10,Ganador,"Empate",Part2Empate4L,$CH10)) -> 0 | CK10: =IF($CH10="-","-",COUNTIFS(FGLocal,$BD10,Ganador,"Visitante",Part2Empate4V,$CH10)+COUNTIFS(FGVisitante,$BD10,Ganador,"Local",Part2Empate4L,$CH10)) -> 0 | CL10: =IF($CH10="-","-",CI10*3+CJ10) -> 0 | CM10: =CG10+COUNTIFS($CH$6:$CH$53,CH10,$CL$6:CL$53,">"&CL10,$BC$6:$BC$53,INDEX(T_Equipos[Grupo],MATCH(BD10,T_Equipos[NombreEquipo],0))) -> 1 | CN10: =IF(COUNTIFS($CM$6:$CM$53,CM10,$BC$6:$BC$53,INDEX(T_Equipos[Grupo],MATCH(BD10,T_Equipos[NombreEquipo],0)))=1,"-","P."&CM10&" ("&COUNTIFS($CM$6:$CM$53,CM10,$BC$6:$BC$53,INDEX(T_Equipos[Grupo],MATCH(BD10,T_Equipos[NombreEquipo],0)))&")") -> P.1 (4) | CO10: =IF($CN10="-","-",SUMIFS(FG_GolesLocal,FGLocal,$BD10,Part2Empate5V,$CN10)+SUMIFS(FG_GolesVisitante,FGVisitante,$BD10,Part2Empate5L,$CN10)) -> 0 | CP10: =IF($CN10="-","-",SUMIFS(FG_GolesVisitante,FGLocal,$BD10,Part2Empate5V,$CN10)+SUMIFS(FG_GolesLocal,FGVisitante,$BD10,Part2Empate5L,$CN10)) -> 0 | CQ10: =IF($CN10="-","-",CO10-CP10) -> 0 | CR10: =CM10+COUNTIFS($CN$6:$CN$53,CN10,$CQ$6:CQ$53,">"&CQ10,$BC$6:$BC$53,INDEX(T_Equipos[Grupo],MATCH(BD10,T_Equipos[NombreEquipo],0))) -> 1 | CS10: =IF(COUNTIFS($CR$6:$CR$53,CR10,$BC$6:$BC$53,INDEX(T_Equipos[Grupo],MATCH(BD10,T_Equipos[NombreEquipo],0)))=1,"-","P."&CR10&" ("&COUNTIFS($CR$6:$CR$53,CR10,$BC$6:$BC$53,INDEX(T_Equipos[Grupo],MATCH(BD10,T_Equipos[NombreEquipo],0)))&")") -> P.1 (4) | CT10: =IF($CS10="-","-",SUMIFS(FG_GolesLocal,FGLocal,$BD10,Part2Empate6V,$CS10)+SUMIFS(FG_GolesVisitante,FGVisitante,$BD10,Part2Empate6L,$CS10)) -> 0 | CU10: =CR10+COUNTIFS($CS$6:$CS$53,CS10,$CT$6:CT$53,">"&CT10,$BC$6:$BC$53,INDEX(T_Equipos[Grupo],MATCH(BD10,T_Equipos[NombreEquipo],0))) -> 1 | CV10: =IF(COUNTIFS($CU$6:$CU$53,CU10,$BC$6:$BC$53,INDEX(T_Equipos[Grupo],MATCH(BD10,T_Equipos[NombreEquipo],0)))=1,"-","P."&CU10&" ("&COUNTIFS($CU$6:$CU$53,CU10,$BC$6:$BC$53,INDEX(T_Equipos[Grupo],MATCH(BD10,T_Equipos[NombreEquipo],0)))&")") -> P.1 (4) | CW10: =IF(CV10="-","-",BL10) -> 0 | CX10: =CU10+COUNTIFS($CV$6:$CV$53,CV10,$CW$6:CW$53,">"&CW10,$BC$6:$BC$53,INDEX(T_Equipos[Grupo],MATCH(BD10,T_Equipos[NombreEquipo],0))) -> 1 | CY10: =IF(COUNTIFS($CX$6:$CX$53,CX10,$BC$6:$BC$53,INDEX(T_Equipos[Grupo],MATCH(BD10,T_Equipos[NombreEquipo],0)))=1,"-","P."&CX10&" ("&COUNTIFS($CX$6:$CX$53,CX10,$BC$6:$BC$53,INDEX(T_Equipos[Grupo],MATCH(BD10,T_Equipos[NombreEquipo],0)))&")") -> P.1 (4) | CZ10: =IF(CY10="-","-",BJ10) -> 0 | DA10: =CX10+COUNTIFS($CY$6:$CY$53,CY10,$CZ$6:CZ$53,">"&CZ10,$BC$6:$BC$53,INDEX(T_Equipos[Grupo],MATCH(BD10,T_Equipos[NombreEquipo],0))) -> 1 | DB10: =IF(COUNTIFS($DA$6:$DA$53,DA10,$BC$6:$BC$53,INDEX(T_Equipos[Grupo],MATCH(BD10,T_Equipos[NombreEquipo],0)))=1,"-","P."&DA10&" ("&COUNTIFS($DA$6:$DA$53,DA10,$BC$6:$BC$53,INDEX(T_Equipos[Grupo],MATCH(BD10,T_Equipos[NombreEquipo],0)))&")") -> P.1 (4) | DC10: =IF(DB10="-","-",COUNTIFS(T_Equipos[Rank],"<"&INDEX(T_Equipos[Rank],MATCH(BD10,T_Equipos[NombreEquipo],0)),$BC$6:$BC$53,INDEX(T_Equipos[Grupo],MATCH(BD10,T_Equipos[NombreEquipo],0)))+1) -> 1 | DD10: =DA10+COUNTIFS($DB$6:$DB$53,DB10,$DC$6:DC$53,"<"&DC10,$BC$6:$BC$53,INDEX(T_Equipos[Grupo],MATCH(BD10,T_Equipos[NombreEquipo],0))) -> 1 | DF10: =IF(OR(INDEX($AW$6:$AW$97,MATCH($BD10,$AV$6:$AV$97,0))="",DB10="-"),DD10,INDEX($AW$6:$AW$97,MATCH($BD10,$AV$6:$AV$97,0))+DD10/1000) -> 1 | DG10: =IF(DB10="-","-",COUNTIFS(DF$6:DF$53,"<"&DF10,$BC$6:$BC$53,INDEX(T_Equipos[Grupo],MATCH(BD10,T_Equipos[NombreEquipo],0)))) -> 0 | DH10: =DA10+COUNTIFS(DB$6:DB$53,DB10,DG$6:DG$53,"<"&DG10,$BC$6:$BC$53,INDEX(T_Equipos[Grupo],MATCH(BD10,T_Equipos[NombreEquipo],0))) -> 1 | DJ10: =INDEX($DA$6:$DA$53,MATCH($DQ10,$BD$6:$BD$53,0)) -> 1 | DK10: =+SUMIF($BC$6:$BC$53,BC10,$BF$6:$BF$53) -> 0 | DL10: =IF(OR(DK10=12,$AJ$99=144),COUNTIFS($DJ$6:$DJ$53,DJ10,$BC$6:$BC$53,BC10),1) -> 1 | DM10: =DJ10&"."&DL10 -> 1.1 | DN10: {=OFFSET(Horarios!$P$3,DJ10-1,0,DL10,1)} -> 1 | DP10: 1B | DQ10: =INDEX($BD$6:$BD$53,MATCH(DP10,$BM$6:$BM$53,0)) -> Canadá | DT10: =AA10&"-"&AF10 -> -
